Workbook

Sheet Documentation
A1: BSO data | B1: The useful floor area per country as 2020 in m2 (Residential & Service)
A2: heat_spec_distribution | B2: share of construction year in total floor area of a country, assumption for each construction year spec. Heat
A3: heat_demand_by_country_TWh | B3: the total heat demand of each country in TWh, calculated based on share of floor area in different construction years and their spec. Heat
A4: elec_demand_heating_TWh | B4: total electricity demand for heating in TWh, calculated from

Sheet BSO data
A1: Unit | C1: m2 | D1: m2
A2: Sector | C2: Residential | D2: Service
A3: Construction period | B3: Country | C3: value | D3: value
A4: 0-1945 | B4: Austria | C4: 108909872 | D4: 18729410 | E4: =SUM(C4) -> 108909872
A5: 0-1945 | B5: Belgium | C5: 285731747 | D5: 93229643 | E5: =SUM(C5) -> 285731747
A6: 0-1945 | B6: Bulgaria | C6: 66932083 | D6: 18336880 | E6: =SUM(C6) -> 66932083
A7: 0-1945 | B7: Croatia | C7: 23713301 | D7: 5442954 | E7: =SUM(C7) -> 23713301
A8: 0-1945 | B8: Cyprus | C8: 7245195 | D8: 9759724 | E8: =SUM(C8) -> 7245195
A9: 0-1945 | B9: Czechia | C9: 69149239 | D9: 81621975 | E9: =SUM(C9) -> 69149239
A10: 0-1945 | B10: Denmark | C10: 70528445 | D10: 15879767 | E10: =SUM(C10) -> 70528445
A11: 0-1945 | B11: Estonia | C11: 9082825 | D11: 2820744 | E11: =SUM(C11) -> 9082825
A12: 0-1945 | B12: Finland | C12: 59734692 | D12: 12895469 | E12: =SUM(C12) -> 59734692
A13: 0-1945 | B13: France | C13: 563983513 | D13: 433418907 | E13: =SUM(C13) -> 563983513
A14: 0-1945 | B14: Germany | C14: 814782438 | D14: 347880057 | E14: =SUM(C14) -> 814782438
A15: 0-1945 | B15: Greece | C15: 46846238 | D15: 43072893 | E15: =SUM(C15) -> 46846238
... A192: 2011-now | B192: Sweden | C192: 52286959 | D192: 7356079 | E192: =SUM(C192) -> 52286959
A194: Applied filters: Year is not 2023 Country is not EU27 Subject is Useful floor area Granularity 1 is Construction period Granularity 2 is Sector

Sheet heat_spec_distribution
A1: Country | B1: gesamtfläche_m2 | C1: anteil 0-1945 | D1: anteil 1946-1969 | E1: anteil 1970-1979 | F1: anteil 1980-1989 | G1: anteil 1990-1999 | H1: anteil 2000-2010 | I1: anteil 2011-now
A2: Austria | B2: ='BSO data'!E4+'BSO data'!E31+'BSO data'!E58+'BSO data'!E85+'BSO data'!E112+'BSO data'!E139+'BSO data'!E166 -> 480479871 | C2: ='BSO data'!E4/heat_spec_distribution!B2 -> 0.22666896 | D2: ='BSO data'!E31/heat_spec_distribution!B2 -> 0.26568905 | E2: ='BSO data'!E58/heat_spec_distribution!B2 -> 0.15349736 | F2: ='BSO data'!E85/heat_spec_distribution!B2 -> 0.12312471 | G2: ='BSO data'!E112/heat_spec_distribution!B2 -> 0.14120436 | H2: ='BSO data'!E139/heat_spec_distribution!B2 -> 0.069105138 | I2: ='BSO data'!E166/heat_spec_distribution!B2 -> 0.02071042
A3: Belgium | B3: ='BSO data'!E5+'BSO data'!E32+'BSO data'!E59+'BSO data'!E86+'BSO data'!E113+'BSO data'!E140+'BSO data'!E167 -> 693785280 | C3: ='BSO data'!E5/heat_spec_distribution!B3 -> 0.41184464 | D3: ='BSO data'!E32/heat_spec_distribution!B3 -> 0.21794057 | E3: ='BSO data'!E59/heat_spec_distribution!B3 -> 0.12174735 | F3: ='BSO data'!E86/heat_spec_distribution!B3 -> 0.084841144 | G3: ='BSO data'!E113/heat_spec_distribution!B3 -> 0.064261007 | H3: ='BSO data'!E140/heat_spec_distribution!B3 -> 0.062943245 | I3: ='BSO data'!E167/heat_spec_distribution!B3 -> 0.03642205
A4: Bulgaria | B4: ='BSO data'!E6+'BSO data'!E33+'BSO data'!E60+'BSO data'!E87+'BSO data'!E114+'BSO data'!E141+'BSO data'!E168 -> 321201659 | C4: ='BSO data'!E6/heat_spec_distribution!B4 -> 0.20838025 | D4: ='BSO data'!E33/heat_spec_distribution!B4 -> 0.22674849 | E4: ='BSO data'!E60/heat_spec_distribution!B4 -> 0.14595338 | F4: ='BSO data'!E87/heat_spec_distribution!B4 -> 0.13737596 | G4: ='BSO data'!E114/heat_spec_distribution!B4 -> 0.10716671 | H4: ='BSO data'!E141/heat_spec_distribution!B4 -> 0.11118345 | I4: ='BSO data'!E168/heat_spec_distribution!B4 -> 0.06319175
A5: Croatia | B5: ='BSO data'!E7+'BSO data'!E34+'BSO data'!E61+'BSO data'!E88+'BSO data'!E115+'BSO data'!E142+'BSO data'!E169 -> 182977135 | C5: ='BSO data'!E7/heat_spec_distribution!B5 -> 0.12959707 | D5: ='BSO data'!E34/heat_spec_distribution!B5 -> 0.17113553 | E5: ='BSO data'!E61/heat_spec_distribution!B5 -> 0.18395604 | F5: ='BSO data'!E88/heat_spec_distribution!B5 -> 0.14058608 | G5: ='BSO data'!E115/heat_spec_distribution!B5 -> 0.12849816 | H5: ='BSO data'!E142/heat_spec_distribution!B5 -> 0.15721611 | I5: ='BSO data'!E169/heat_spec_distribution!B5 -> 0.08901099
A6: Cyprus | B6: ='BSO data'!E8+'BSO data'!E35+'BSO data'!E62+'BSO data'!E89+'BSO data'!E116+'BSO data'!E143+'BSO data'!E170 -> 92282979 | C6: ='BSO data'!E8/heat_spec_distribution!B6 -> 0.078510632 | D6: ='BSO data'!E35/heat_spec_distribution!B6 -> 0.32212068 | E6: ='BSO data'!E62/heat_spec_distribution!B6 -> 0.17328696 | F6: ='BSO data'!E89/heat_spec_distribution!B6 -> 0.072024387 | G6: ='BSO data'!E116/heat_spec_distribution!B6 -> 0.061453023 | H6: ='BSO data'!E143/heat_spec_distribution!B6 -> 0.1944297 | I6: ='BSO data'!E170/heat_spec_distribution!B6 -> 0.098174616
A7: Czechia | B7: ='BSO data'!E9+'BSO data'!E36+'BSO data'!E63+'BSO data'!E90+'BSO data'!E117+'BSO data'!E144+'BSO data'!E171 -> 387472106 | C7: ='BSO data'!E9/heat_spec_distribution!B7 -> 0.1784625 | D7: ='BSO data'!E36/heat_spec_distribution!B7 -> 0.20868347 | E7: ='BSO data'!E63/heat_spec_distribution!B7 -> 0.20364145 | F7: ='BSO data'!E90/heat_spec_distribution!B7 -> 0.12788671 | G7: ='BSO data'!E117/heat_spec_distribution!B7 -> 0.087488329 | H7: ='BSO data'!E144/heat_spec_distribution!B7 -> 0.11549953 | I7: ='BSO data'!E171/heat_spec_distribution!B7 -> 0.078338003
A8: Denmark | B8: ='BSO data'!E10+'BSO data'!E37+'BSO data'!E64+'BSO data'!E91+'BSO data'!E118+'BSO data'!E145+'BSO data'!E172 -> 341768565 | C8: ='BSO data'!E10/heat_spec_distribution!B8 -> 0.20636317 | D8: ='BSO data'!E37/heat_spec_distribution!B8 -> 0.18265735 | E8: ='BSO data'!E64/heat_spec_distribution!B8 -> 0.20054756 | F8: ='BSO data'!E91/heat_spec_distribution!B8 -> 0.10100399 | G8: ='BSO data'!E118/heat_spec_distribution!B8 -> 0.10050849 | H8: ='BSO data'!E145/heat_spec_distribution!B8 -> 0.1065849 | I8: ='BSO data'!E172/heat_spec_distribution!B8 -> 0.10233454
A9: Estonia | B9: ='BSO data'!E11+'BSO data'!E38+'BSO data'!E65+'BSO data'!E92+'BSO data'!E119+'BSO data'!E146+'BSO data'!E173 -> 27472583 | C9: ='BSO data'!E11/heat_spec_distribution!B9 -> 0.33061416 | D9: ='BSO data'!E38/heat_spec_distribution!B9 -> 0.21114669 | E9: ='BSO data'!E65/heat_spec_distribution!B9 -> 0.085552713 | F9: ='BSO data'!E92/heat_spec_distribution!B9 -> 0.076144096 | G9: ='BSO data'!E119/heat_spec_distribution!B9 -> 0.11793583 | H9: ='BSO data'!E146/heat_spec_distribution!B9 -> 0.1150914 | I9: ='BSO data'!E173/heat_spec_distribution!B9 -> 0.063515105
A10: Finland | B10: ='BSO data'!E12+'BSO data'!E39+'BSO data'!E66+'BSO data'!E93+'BSO data'!E120+'BSO data'!E147+'BSO data'!E174 -> 406877934 | C10: ='BSO data'!E12/heat_spec_distribution!B10 -> 0.14681232 | D10: ='BSO data'!E39/heat_spec_distribution!B10 -> 0.23466125 | E10: ='BSO data'!E66/heat_spec_distribution!B10 -> 0.14795198 | F10: ='BSO data'!E93/heat_spec_distribution!B10 -> 0.18673125 | G10: ='BSO data'!E120/heat_spec_distribution!B10 -> 0.12341815 | H10: ='BSO data'!E147/heat_spec_distribution!B10 -> 0.13390438 | I10: ='BSO data'!E174/heat_spec_distribution!B10 -> 0.026520664
A11: France | B11: ='BSO data'!E13+'BSO data'!E40+'BSO data'!E67+'BSO data'!E94+'BSO data'!E121+'BSO data'!E148+'BSO data'!E175 -> 3087013302 | C11: ='BSO data'!E13/heat_spec_distribution!B11 -> 0.18269552 | D11: ='BSO data'!E40/heat_spec_distribution!B11 -> 0.14157618 | E11: ='BSO data'!E67/heat_spec_distribution!B11 -> 0.15598287 | F11: ='BSO data'!E94/heat_spec_distribution!B11 -> 0.14948863 | G11: ='BSO data'!E121/heat_spec_distribution!B11 -> 0.098669292 | H11: ='BSO data'!E148/heat_spec_distribution!B11 -> 0.14705403 | I11: ='BSO data'!E175/heat_spec_distribution!B11 -> 0.12453347
A12: Germany | B12: ='BSO data'!E14+'BSO data'!E41+'BSO data'!E68+'BSO data'!E95+'BSO data'!E122+'BSO data'!E149+'BSO data'!E176 -> 3808633334 | C12: ='BSO data'!E14/heat_spec_distribution!B12 -> 0.2139304 | D12: ='BSO data'!E41/heat_spec_distribution!B12 -> 0.30219613 | E12: ='BSO data'!E68/heat_spec_distribution!B12 -> 0.15222689 | F12: ='BSO data'!E95/heat_spec_distribution!B12 -> 0.1073582 | G12: ='BSO data'!E122/heat_spec_distribution!B12 -> 0.10540157 | H12: ='BSO data'!E149/heat_spec_distribution!B12 -> 0.076124592 | I12: ='BSO data'!E176/heat_spec_distribution!B12 -> 0.042762236
A13: Greece | B13: ='BSO data'!E15+'BSO data'!E42+'BSO data'!E69+'BSO data'!E96+'BSO data'!E123+'BSO data'!E150+'BSO data'!E177 -> 574209913 | C13: ='BSO data'!E15/heat_spec_distribution!B13 -> 0.08158382 | D13: ='BSO data'!E42/heat_spec_distribution!B13 -> 0.22652044 | E13: ='BSO data'!E69/heat_spec_distribution!B13 -> 0.19074206 | F13: ='BSO data'!E96/heat_spec_distribution!B13 -> 0.22318758 | G13: ='BSO data'!E123/heat_spec_distribution!B13 -> 0.16231306 | H13: ='BSO data'!E150/heat_spec_distribution!B13 -> 0.062897023 | I13: ='BSO data'!E177/heat_spec_distribution!B13 -> 0.052756017
... A28: Sweden | B28: ='BSO data'!E30+'BSO data'!E57+'BSO data'!E84+'BSO data'!E111+'BSO data'!E138+'BSO data'!E165+'BSO data'!E192 -> 486603092 | C28: ='BSO data'!E30/heat_spec_distribution!B28 -> 0.18329553 | D28: ='BSO data'!E57/heat_spec_distribution!B28 -> 0.15925786 | E28: ='BSO data'!E84/heat_spec_distribution!B28 -> 0.15803127 | F28: ='BSO data'!E111/heat_spec_distribution!B28 -> 0.14616061 | G28: ='BSO data'!E138/heat_spec_distribution!B28 -> 0.12511941 | H28: ='BSO data'!E165/heat_spec_distribution!B28 -> 0.12068232 | I28: ='BSO data'!E192/heat_spec_distribution!B28 -> 0.10745299
B31: construction year | C31: 0-1945 | D31: 1946-1969 | E31: 1970-1979 | F31: 1980-1989 | G31: 1990-1999 | H31: 2000-2010 | I31: 2011-now
B32: Heat_spec_assumptions [kWh/m2] | C32: 200 | D32: 175 | E32: 150 | F32: 125 | G32: 100 | H32: 75 | I32: 50
B34: Country Category | C34: ES, PT, IT, GR, HR, SI | D34: FR, DE, AT, BE, NL, LU, IE | E34: PL, CZ, SK, HU, RO, BG | F34: SE, FI, NO, DK, EE, LV, LT
B35: COP | C35: 3.3 | D35: 3 | E35: 2.7 | F35: 2.5

Sheet heat_demand_by_country_TWh
A1: Country | B1: 2020 | C1: 2021 | D1: 2022 | E1: 2023 | F1: 2024 | G1: 2025 | H1: 2026 | I1: 2027 | J1: 2028 | K1: 2029 | L1: 2030 | M1: 2031 | N1: 2032 | O1: 2033 | P1: 2034 | Q1: 2035 | R1: 2036 | S1: 2037 | T1: 2038 | U1: 2039 | V1: 2040 | W1: 2041 | X1: 2042 | Y1: 2043 | Z1: 2044 | AA1: 2045 | AB1: 2046 | AC1: 2047 | AD1: 2048 | AE1: 2049 | AF1: 2050 | AG1: 2051 | AH1: 2052 | AI1: 2053 | AJ1: 2054 | AK1: 2055 | AL1: 2056 | AM1: 2057 | AN1: 2058 | AO1: 2059 | AP1: 2060
A2: Austria | B2: =heat_spec_distribution!B2/1000000000*(heat_spec_distribution!C2*heat_spec_distribution!C$32+heat_spec_distribution!D2*heat_spec_distribution!D$32+heat_spec_distribution!E2*heat_spec_distribution!E$32+heat_spec_distribution!F2*heat_spec_distribution!F$32+heat_spec_distribution!G2*heat_spec_distribution!G$32+heat_spec_distribution!H2*heat_spec_distribution!H$32+heat_spec_distribution!I2*heat_spec_distribution!I$32) -> 72.352298
A3: Belgium | B3: =heat_spec_distribution!B3/1000000000*(heat_spec_distribution!C3*heat_spec_distribution!C$32+heat_spec_distribution!D3*heat_spec_distribution!D$32+heat_spec_distribution!E3*heat_spec_distribution!E$32+heat_spec_distribution!F3*heat_spec_distribution!F$32+heat_spec_distribution!G3*heat_spec_distribution!G$32+heat_spec_distribution!H3*heat_spec_distribution!H$32+heat_spec_distribution!I3*heat_spec_distribution!I$32) -> 112.63168
A4: Bulgaria | B4: =heat_spec_distribution!B4/1000000000*(heat_spec_distribution!C4*heat_spec_distribution!C$32+heat_spec_distribution!D4*heat_spec_distribution!D$32+heat_spec_distribution!E4*heat_spec_distribution!E$32+heat_spec_distribution!F4*heat_spec_distribution!F$32+heat_spec_distribution!G4*heat_spec_distribution!G$32+heat_spec_distribution!H4*heat_spec_distribution!H$32+heat_spec_distribution!I4*heat_spec_distribution!I$32) -> 45.815259
A5: Croatia | B5: =heat_spec_distribution!B5/1000000000*(heat_spec_distribution!C5*heat_spec_distribution!C$32+heat_spec_distribution!D5*heat_spec_distribution!D$32+heat_spec_distribution!E5*heat_spec_distribution!E$32+heat_spec_distribution!F5*heat_spec_distribution!F$32+heat_spec_distribution!G5*heat_spec_distribution!G$32+heat_spec_distribution!H5*heat_spec_distribution!H$32+heat_spec_distribution!I5*heat_spec_distribution!I$32) -> 23.810151
A6: Cyprus | B6: =heat_spec_distribution!B6/1000000000*(heat_spec_distribution!C6*heat_spec_distribution!C$32+heat_spec_distribution!D6*heat_spec_distribution!D$32+heat_spec_distribution!E6*heat_spec_distribution!E$32+heat_spec_distribution!F6*heat_spec_distribution!F$32+heat_spec_distribution!G6*heat_spec_distribution!G$32+heat_spec_distribution!H6*heat_spec_distribution!H$32+heat_spec_distribution!I6*heat_spec_distribution!I$32) -> 12.246468
A7: Czechia | B7: =heat_spec_distribution!B7/1000000000*(heat_spec_distribution!C7*heat_spec_distribution!C$32+heat_spec_distribution!D7*heat_spec_distribution!D$32+heat_spec_distribution!E7*heat_spec_distribution!E$32+heat_spec_distribution!F7*heat_spec_distribution!F$32+heat_spec_distribution!G7*heat_spec_distribution!G$32+heat_spec_distribution!H7*heat_spec_distribution!H$32+heat_spec_distribution!I7*heat_spec_distribution!I$32) -> 54.274133
A8: Denmark | B8: =heat_spec_distribution!B8/1000000000*(heat_spec_distribution!C8*heat_spec_distribution!C$32+heat_spec_distribution!D8*heat_spec_distribution!D$32+heat_spec_distribution!E8*heat_spec_distribution!E$32+heat_spec_distribution!F8*heat_spec_distribution!F$32+heat_spec_distribution!G8*heat_spec_distribution!G$32+heat_spec_distribution!H8*heat_spec_distribution!H$32+heat_spec_distribution!I8*heat_spec_distribution!I$32) -> 47.542313
A9: Estonia | B9: =heat_spec_distribution!B9/1000000000*(heat_spec_distribution!C9*heat_spec_distribution!C$32+heat_spec_distribution!D9*heat_spec_distribution!D$32+heat_spec_distribution!E9*heat_spec_distribution!E$32+heat_spec_distribution!F9*heat_spec_distribution!F$32+heat_spec_distribution!G9*heat_spec_distribution!G$32+heat_spec_distribution!H9*heat_spec_distribution!H$32+heat_spec_distribution!I9*heat_spec_distribution!I$32) -> 4.0941186
A10: Finland | B10: =heat_spec_distribution!B10/1000000000*(heat_spec_distribution!C10*heat_spec_distribution!C$32+heat_spec_distribution!D10*heat_spec_distribution!D$32+heat_spec_distribution!E10*heat_spec_distribution!E$32+heat_spec_distribution!F10*heat_spec_distribution!F$32+heat_spec_distribution!G10*heat_spec_distribution!G$32+heat_spec_distribution!H10*heat_spec_distribution!H$32+heat_spec_distribution!I10*heat_spec_distribution!I$32) -> 56.829887
A11: France | B11: =heat_spec_distribution!B11/1000000000*(heat_spec_distribution!C11*heat_spec_distribution!C$32+heat_spec_distribution!D11*heat_spec_distribution!D$32+heat_spec_distribution!E11*heat_spec_distribution!E$32+heat_spec_distribution!F11*heat_spec_distribution!F$32+heat_spec_distribution!G11*heat_spec_distribution!G$32+heat_spec_distribution!H11*heat_spec_distribution!H$32+heat_spec_distribution!I11*heat_spec_distribution!I$32) -> 402.92037
A12: Germany | B12: =heat_spec_distribution!B12/1000000000*(heat_spec_distribution!C12*heat_spec_distribution!C$32+heat_spec_distribution!D12*heat_spec_distribution!D$32+heat_spec_distribution!E12*heat_spec_distribution!E$32+heat_spec_distribution!F12*heat_spec_distribution!F$32+heat_spec_distribution!G12*heat_spec_distribution!G$32+heat_spec_distribution!H12*heat_spec_distribution!H$32+heat_spec_distribution!I12*heat_spec_distribution!I$32) -> 572.48261
A13: Greece | B13: =heat_spec_distribution!B13/1000000000*(heat_spec_distribution!C13*heat_spec_distribution!C$32+heat_spec_distribution!D13*heat_spec_distribution!D$32+heat_spec_distribution!E13*heat_spec_distribution!E$32+heat_spec_distribution!F13*heat_spec_distribution!F$32+heat_spec_distribution!G13*heat_spec_distribution!G$32+heat_spec_distribution!H13*heat_spec_distribution!H$32+heat_spec_distribution!I13*heat_spec_distribution!I$32) -> 78.123545
... A28: Sweden | B28: =heat_spec_distribution!B28/1000000000*(heat_spec_distribution!C28*heat_spec_distribution!C$32+heat_spec_distribution!D28*heat_spec_distribution!D$32+heat_spec_distribution!E28*heat_spec_distribution!E$32+heat_spec_distribution!F28*heat_spec_distribution!F$32+heat_spec_distribution!G28*heat_spec_distribution!G$32+heat_spec_distribution!H28*heat_spec_distribution!H$32+heat_spec_distribution!I28*heat_spec_distribution!I$32) -> 64.932202
A32: Country Category | B32: ES, PT, IT, GR, HU, SI | C32: FR, DE, AT, BE, NL, LU, IE | D32: PL, CZ, SK, HR, RO, BG | E32: SE, FI, NO, DK, EE, LV, LT
A33: COP | B33: 3.3 | C33: 3 | D33: 2.7 | E33: 2.5

Sheet elect_demand_heating_TWh
A1: Country | B1: 2020 | C1: 2021 | D1: 2022 | E1: 2023 | F1: 2024 | G1: 2025 | H1: 2026 | I1: 2027 | J1: 2028 | K1: 2029 | L1: 2030 | M1: 2031 | N1: 2032 | O1: 2033 | P1: 2034 | Q1: 2035 | R1: 2036 | S1: 2037 | T1: 2038 | U1: 2039 | V1: 2040 | W1: 2041 | X1: 2042 | Y1: 2043 | Z1: 2044 | AA1: 2045 | AB1: 2046 | AC1: 2047 | AD1: 2048 | AE1: 2049 | AF1: 2050 | AG1: 2051 | AH1: 2052 | AI1: 2053 | AJ1: 2054 | AK1: 2055 | AL1: 2056 | AM1: 2057 | AN1: 2058 | AO1: 2059 | AP1: 2060
A2: Austria | B2: =heat_demand_by_country_TWh!B2/heat_demand_by_country_TWh!$C$33 -> 24.117433
A3: Belgium | B3: =heat_demand_by_country_TWh!B3/heat_demand_by_country_TWh!$C$33 -> 37.543894
A4: Bulgaria | B4: =heat_demand_by_country_TWh!B4/heat_demand_by_country_TWh!$D$33 -> 16.968614
A5: Croatia | B5: =heat_demand_by_country_TWh!B5/heat_demand_by_country_TWh!$D$33 -> 8.8185745
A6: Cyprus | B6: =heat_demand_by_country_TWh!B6/heat_demand_by_country_TWh!$B$33 -> 3.7110509
A7: Czechia | B7: =heat_demand_by_country_TWh!B7/heat_demand_by_country_TWh!$D$33 -> 20.101531
A8: Denmark | B8: =heat_demand_by_country_TWh!B8/heat_demand_by_country_TWh!$E$33 -> 19.016925
A9: Estonia | B9: =heat_demand_by_country_TWh!B9/heat_demand_by_country_TWh!$E$33 -> 1.6376474
A10: Finland | B10: =heat_demand_by_country_TWh!B10/heat_demand_by_country_TWh!$E$33 -> 22.731955
A11: France | B11: =heat_demand_by_country_TWh!B11/heat_demand_by_country_TWh!$C$33 -> 134.30679
A12: Germany | B12: =heat_demand_by_country_TWh!B12/heat_demand_by_country_TWh!$C$33 -> 190.82754
A13: Greece | B13: =heat_demand_by_country_TWh!B13/heat_demand_by_country_TWh!$B$33 -> 23.673801
A14: Hungary | B14: =heat_demand_by_country_TWh!B14/heat_demand_by_country_TWh!$B$33 -> 12.982014
A15: Ireland | B15: =heat_demand_by_country_TWh!B15/heat_demand_by_country_TWh!$C$33 -> 9.4176021
A16: Italy | B16: =heat_demand_by_country_TWh!B16/heat_demand_by_country_TWh!$B$33 -> 131.8336
A17: Latvia | B17: =heat_demand_by_country_TWh!B17/heat_demand_by_country_TWh!$E$33 -> 3.4997695
A18: Lithuania | B18: =heat_demand_by_country_TWh!B18/heat_demand_by_country_TWh!$E$33 -> 7.0435599
A19: Luxembourg | B19: =heat_demand_by_country_TWh!B19/heat_demand_by_country_TWh!$C$33 -> 1.3530466
A20: Malta | B20: =heat_demand_by_country_TWh!B20/heat_demand_by_country_TWh!$B$33 -> 1.0364506
A21: Netherlands | B21: =heat_demand_by_country_TWh!B21/heat_demand_by_country_TWh!$C$33 -> 33.838843
A22: Poland | B22: =heat_demand_by_country_TWh!B22/heat_demand_by_country_TWh!$D$33 -> 50.098429
A23: Portugal | B23: =heat_demand_by_country_TWh!B23/heat_demand_by_country_TWh!$B$33 -> 24.002222
A24: Romania | B24: =heat_demand_by_country_TWh!B24/heat_demand_by_country_TWh!$D$33 -> 20.692284
A25: Slovakia | B25: =heat_demand_by_country_TWh!B25/heat_demand_by_country_TWh!$D$33 -> 8.8340031
A26: Slovenia | B26: =heat_demand_by_country_TWh!B26/heat_demand_by_country_TWh!$B$33 -> 2.7368577
A27: Spain | B27: =heat_demand_by_country_TWh!B27/heat_demand_by_country_TWh!$B$33 -> 144.90774
A28: Sweden | B28: =heat_demand_by_country_TWh!B28/heat_demand_by_country_TWh!$E$33 -> 25.972881

Sheet elec_Demand_HP_TWh
A1: Country | B1: 2020 | C1: 2021 | D1: 2022 | E1: 2023 | F1: 2024 | G1: 2025 | H1: 2026 | I1: 2027 | J1: 2028 | K1: 2029 | L1: 2030 | M1: 2031 | N1: 2032 | O1: 2033 | P1: 2034 | Q1: 2035 | R1: 2036 | S1: 2037 | T1: 2038 | U1: 2039 | V1: 2040 | W1: 2041 | X1: 2042 | Y1: 2043 | Z1: 2044 | AA1: 2045 | AB1: 2046 | AC1: 2047 | AD1: 2048 | AE1: 2049 | AF1: 2050 | AG1: 2051 | AH1: 2052 | AI1: 2053 | AJ1: 2054 | AK1: 2055 | AL1: 2056 | AM1: 2057 | AN1: 2058 | AO1: 2059 | AP1: 2060
A2: Austria
A3: Belgium
A4: Bulgaria
A5: Croatia
A6: Cyprus
A7: Czechia
A8: Denmark
A9: Estonia
A10: Finland
A11: France
A12: Germany
A13: Greece
... A28: Sweden

Sheet new_building_eurostat
A1: Data extracted on 15/05/2026 16:24:28 from [ESTAT]
A2: Dataset: | B2: Building permits by type of building - annual data [sts_cobp_a__custom_21476067]
A3: Last updated: | B3: 15/05/2026 11:00
A5: Time frequency | C5: Annual
A6: Business trend indicator | C6: Building permits - m2 of useful floor area
A7: Statistical Classification of Products by Activity (CPA 2.1) | C7: Buildings
A8: Seasonal adjustment | C8: Unadjusted data (i.e. neither seasonally adjusted nor calendar adjusted data)
A9: Unit of measure | C9: Million square metres
A11: TIME | B11: 2021 | C11: Column1 | D11: 2022 | E11: Column2 | F11: 2023 | G11: Column3 | H11: 2024 | I11: Column4 | J11: 2025 | K11: Column5 | L11: Average 2021 - 2025 | M11: Column7 | N11: Column8
A12: Austria | B12: 13.1 | C12: e | D12: 10.7 | E12: e | F12: 8.1 | G12: e | H12: 6.9 | I12: e | J12: 6.5 | K12: e | L12: =AVERAGE(B12,D12,F12,H12,J12) -> 9.06 | M12: Austria | N12: =Table2[[#This Row],[Column7]]=Table2[[#This Row],[TIME]] -> TRUE
A13: Belgium | B13: 18.9 | C13: p | D13: 16.1 | E13: p | F13: 16.2 | G13: p | H13: 14.1 | I13: p | J13: 13.4 | K13: p | L13: =AVERAGE(B13,D13,F13,H13,J13) -> 15.74 | M13: Belgium | N13: =Table2[[#This Row],[Column7]]=Table2[[#This Row],[TIME]] -> TRUE
A14: Bulgaria | B14: 7.4 | C14: i | D14: 8.3 | E14: i | F14: 8.5 | G14: i | H14: 7 | I14: i | J14: 8.6 | K14: i | L14: =AVERAGE(B14,D14,F14,H14,J14) -> 7.96 | M14: Bulgaria | N14: =Table2[[#This Row],[Column7]]=Table2[[#This Row],[TIME]] -> TRUE
A15: Croatia | B15: 2.9 | D15: 3.5 | F15: 3.6 | H15: 3.8 | J15: 3.4 | L15: =AVERAGE(B15,D15,F15,H15,J15) -> 3.44 | M15: Croatia | N15: =Table2[[#This Row],[Column7]]=Table2[[#This Row],[TIME]] -> TRUE
A16: Cyprus | B16: 2.3 | D16: 2.2 | F16: 2.3 | H16: 2.3 | J16: 3.3 | L16: =AVERAGE(B16,D16,F16,H16,J16) -> 2.48 | M16: Cyprus | N16: =Table2[[#This Row],[Column7]]=Table2[[#This Row],[TIME]] -> TRUE
A17: Czechia | B17: 8.5 | C17: i | D17: 8.1 | E17: i | F17: 7.4 | G17: i | H17: 7.4 | I17: i | J17: 6.5 | K17: i | L17: =AVERAGE(B17,D17,F17,H17,J17) -> 7.58 | M17: Czechia | N17: =Table2[[#This Row],[Column7]]=Table2[[#This Row],[TIME]] -> TRUE
A18: Denmark | B18: 10.1 | D18: 8.5 | F18: 6.8 | H18: 6.4 | I18: p | J18: 6.3 | K18: p | L18: =AVERAGE(B18,D18,F18,H18,J18) -> 7.62 | M18: Denmark | N18: =Table2[[#This Row],[Column7]]=Table2[[#This Row],[TIME]] -> TRUE
A19: Estonia | B19: 2 | C19: i | D19: 1.6 | E19: i | F19: 1.5 | G19: i | H19: 1.5 | I19: i | J19: 1.6 | K19: i | L19: =AVERAGE(B19,D19,F19,H19,J19) -> 1.64 | M19: Estonia | N19: =Table2[[#This Row],[Column7]]=Table2[[#This Row],[TIME]] -> TRUE
A20: Finland | B20: 8.9 | D20: 7.2 | F20: 5.7 | H20: 5.3 | J20: 5.3 | L20: =AVERAGE(B20,D20,F20,H20,J20) -> 6.48 | M20: Finland | N20: =Table2[[#This Row],[Column7]]=Table2[[#This Row],[TIME]] -> TRUE
A21: France | B21: 78.5 | C21: i | D21: 80.9 | E21: i | F21: 67.4 | G21: i | H21: 62.8 | I21: i | J21: 66.3 | K21: i | L21: =AVERAGE(B21,D21,F21,H21,J21) -> 71.18 | M21: France | N21: =Table2[[#This Row],[Column7]]=Table2[[#This Row],[TIME]] -> TRUE
A22: Germany | B22: 75 | C22: i | D22: 69.8 | E22: i | F22: 51.7 | G22: i | H22: 45.4 | I22: i | J22: 46.5 | K22: i | L22: =AVERAGE(B22,D22,F22,H22,J22) -> 57.68 | M22: Germany | N22: =Table2[[#This Row],[Column7]]=Table2[[#This Row],[TIME]] -> TRUE
A23: Greece | B23: 3.7 | C23: p | D23: 3.6 | E23: p | F23: 4.2 | G23: i | H23: 5.2 | I23: i | J23: 4.3 | K23: i | L23: =AVERAGE(B23,D23,F23,H23,J23) -> 4.2 | M23: Greece | N23: =Table2[[#This Row],[Column7]]=Table2[[#This Row],[TIME]] -> TRUE
A24: Hungary | B24: 8.4 | C24: i | D24: 9 | E24: i | F24: 7 | G24: i | H24: 5.2 | I24: i | J24: 6 | K24: i | L24: =AVERAGE(B24,D24,F24,H24,J24) -> 7.12 | M24: Hungary | N24: =Table2[[#This Row],[Column7]]=Table2[[#This Row],[TIME]] -> TRUE
A25: Ireland | B25: 7.6 | D25: 6.3 | F25: 6.9 | H25: 6.1 | J25: 6 | L25: =AVERAGE(B25,D25,F25,H25,J25) -> 6.58 | M25: Ireland | N25: =Table2[[#This Row],[Column7]]=Table2[[#This Row],[TIME]] -> TRUE
A26: Italy | B26: 12.7 | C26: i | D26: 13.1 | E26: i | F26: 12.6 | G26: i | H26: 12.8 | I26: i | J26: : | L26: =AVERAGE(B26,D26,F26,H26,J26) -> 12.8 | M26: Italy | N26: =Table2[[#This Row],[Column7]]=Table2[[#This Row],[TIME]] -> TRUE
A27: Latvia | B27: 1.6 | D27: 1.3 | F27: 1.3 | H27: 1.5 | J27: 1.8 | L27: =AVERAGE(B27,D27,F27,H27,J27) -> 1.5 | M27: Latvia | N27: =Table2[[#This Row],[Column7]]=Table2[[#This Row],[TIME]] -> TRUE
A28: Lithuania | B28: 3.6 | D28: 3.1 | F28: 2.9 | H28: 3.5 | J28: 3 | L28: =AVERAGE(B28,D28,F28,H28,J28) -> 3.22 | M28: Lithuania | N28: =Table2[[#This Row],[Column7]]=Table2[[#This Row],[TIME]] -> TRUE
A29: Luxembourg | B29: 1.8 | D29: 1.3 | F29: 1.1 | H29: 0.9 | I29: p | J29: : | L29: =AVERAGE(B29,D29,F29,H29,J29) -> 1.275 | M29: Luxembourg | N29: =Table2[[#This Row],[Column7]]=Table2[[#This Row],[TIME]] -> TRUE
A30: Malta | B30: 1.7 | D30: 2 | F30: 1.7 | H30: 1.8 | J30: 2.5 | L30: =AVERAGE(B30,D30,F30,H30,J30) -> 1.94 | M30: Malta | N30: =Table2[[#This Row],[Column7]]=Table2[[#This Row],[TIME]] -> TRUE
A31: Netherlands | B31: 23.9 | C31: p | D31: 20.4 | E31: p | F31: 16.8 | G31: p | H31: 18.9 | I31: p | J31: 14.8 | K31: p | L31: =AVERAGE(B31,D31,F31,H31,J31) -> 18.96 | M31: Netherlands | N31: =Table2[[#This Row],[Column7]]=Table2[[#This Row],[TIME]] -> TRUE
A32: Norway | B32: 9.7 | D32: : | F32: : | H32: : | J32: : | L32: =AVERAGE(B32,D32,F32,H32,J32) -> 9.7 | N32: =Table2[[#This Row],[Column7]]=Table2[[#This Row],[TIME]] -> FALSE
A33: Poland | B33: 52.2 | D33: 46.6 | F33: 37.7 | H33: 40.8 | J33: 40.7 | L33: =AVERAGE(B33,D33,F33,H33,J33) -> 43.6 | M33: Poland | N33: =Table2[[#This Row],[Column7]]=Table2[[#This Row],[TIME]] -> TRUE
A34: Portugal | B34: 9.1 | D34: 9.5 | E34: p | F34: 9.5 | G34: p | H34: 11.2 | I34: p | J34: 11.3 | K34: p | L34: =AVERAGE(B34,D34,F34,H34,J34) -> 10.12 | M34: Portugal | N34: =Table2[[#This Row],[Column7]]=Table2[[#This Row],[TIME]] -> TRUE
A35: Romania | B35: 15.4 | C35: i | D35: 15.2 | E35: i | F35: 12.7 | G35: i | H35: 12.3 | I35: i | J35: 13.7 | K35: i | L35: =AVERAGE(B35,D35,F35,H35,J35) -> 13.86 | M35: Romania | N35: =Table2[[#This Row],[Column7]]=Table2[[#This Row],[TIME]] -> TRUE
A36: Slovakia | B36: 3.4 | D36: 3 | F36: 3 | H36: 2.7 | J36: 2.5 | K36: p | L36: =AVERAGE(B36,D36,F36,H36,J36) -> 2.92 | M36: Slovakia | N36: =Table2[[#This Row],[Column7]]=Table2[[#This Row],[TIME]] -> TRUE
A37: Slovenia | B37: 1.8 | C37: i | D37: 2.1 | E37: i | F37: 1.8 | G37: i | H37: 1.8 | I37: i | J37: 1.7 | K37: p | L37: =AVERAGE(B37,D37,F37,H37,J37) -> 1.84 | M37: Slovenia | N37: =Table2[[#This Row],[Column7]]=Table2[[#This Row],[TIME]] -> TRUE
A38: Spain | B38: 23.3 | C38: i | D38: 26.1 | E38: i | F38: 28.3 | G38: i | H38: 33.8 | I38: i | J38: 35.6 | K38: i | L38: =AVERAGE(B38,D38,F38,H38,J38) -> 29.42 | M38: Spain | N38: =Table2[[#This Row],[Column7]]=Table2[[#This Row],[TIME]] -> TRUE
A39: Sweden | B39: 14.2 | D39: 12.4 | F39: 8.4 | H39: 7.4 | J39: 8.2 | L39: =AVERAGE(B39,D39,F39,H39,J39) -> 10.12 | M39: Sweden | N39: =Table2[[#This Row],[Column7]]=Table2[[#This Row],[TIME]] -> TRUE
A41: Special value
A42: : | B42: not available
A43: Observation flags:
...

Sheet useful_area_m2
A1: Construction period | B1: Country | C1: 2020 | D1: 2021 | E1: 2022 | F1: 2023 | G1: 2024 | H1: 2025 | I1: 2026 | J1: 2027 | K1: 2028 | L1: 2029 | M1: 2030 | N1: 2031 | O1: 2032 | P1: 2033 | Q1: 2034 | R1: 2035 | S1: 2036 | T1: 2037 | U1: 2038 | V1: 2039 | W1: 2040 | X1: 2041 | Y1: 2042 | Z1: 2043 | AA1: 2044 | AB1: 2045 | AC1: 2046 | AD1: 2047 | AE1: 2048 | AF1: 2049 | AG1: 2050 | AH1: 2051 | AI1: 2052 | AJ1: 2053 | AK1: 2054 | AL1: 2055 | AM1: 2056 | AN1: 2057 | AO1: 2058 | AP1: 2059 | AQ1: 2060
A2: 0-1945 | B2: Austria | C2: 127639282 | D2: =0.997*C2 -> 1.2725636e+08 | E2: =0.997*D2 -> 1.268746e+08 | F2: =0.997*E2 -> 1.2649397e+08 | G2: =0.997*F2 -> 1.2611449e+08 | H2: =0.997*G2 -> 1.2573615e+08 | I2: =0.997*H2 -> 1.2535894e+08 | J2: =0.997*I2 -> 1.2498286e+08 | K2: =0.997*J2 -> 1.2460791e+08 | ... AQ2: =0.997*AP2 -> 1.1318547e+08
A3: 0-1945 | B3: Belgium | C3: 378961390 | D3: =0.997*C3 -> 3.7782451e+08 | E3: =0.997*D3 -> 3.7669103e+08 | F3: =0.997*E3 -> 3.7556096e+08 | G3: =0.997*F3 -> 3.7443428e+08 | H3: =0.997*G3 -> 3.7331097e+08 | I3: =0.997*H3 -> 3.7219104e+08 | J3: =0.997*I3 -> 3.7107447e+08 | K3: =0.997*J3 -> 3.6996124e+08 | ... AQ3: =0.997*AP3 -> 3.3604799e+08
A4: 0-1945 | B4: Bulgaria | C4: 85268963 | D4: =0.997*C4 -> 85013156 | E4: =0.997*D4 -> 84758117 | F4: =0.997*E4 -> 84503842 | G4: =0.997*F4 -> 84250331 | H4: =0.997*G4 -> 83997580 | I4: =0.997*H4 -> 83745587 | J4: =0.997*I4 -> 83494350 | K4: =0.997*J4 -> 83243867 | ... AQ4: =0.997*AP4 -> 75613147
A5: 0-1945 | B5: Croatia | C5: 29156255 | D5: =0.997*C5 -> 29068786 | E5: =0.997*D5 -> 28981580 | F5: =0.997*E5 -> 28894635 | G5: =0.997*F5 -> 28807951 | H5: =0.997*G5 -> 28721527 | I5: =0.997*H5 -> 28635363 | J5: =0.997*I5 -> 28549457 | K5: =0.997*J5 -> 28463808 | ... AQ5: =0.997*AP5 -> 25854615
A6: 0-1945 | B6: Cyprus | C6: 17004919 | D6: =0.997*C6 -> 16953904 | E6: =0.997*D6 -> 16903043 | F6: =0.997*E6 -> 16852333 | G6: =0.997*F6 -> 16801776 | H6: =0.997*G6 -> 16751371 | I6: =0.997*H6 -> 16701117 | J6: =0.997*I6 -> 16651014 | K6: =0.997*J6 -> 16601061 | ... AQ6: =0.997*AP6 -> 15079290
A7: 0-1945 | B7: Czechia | C7: 150771214 | D7: =0.997*C7 -> 1.503189e+08 | E7: =0.997*D7 -> 1.4986794e+08 | F7: =0.997*E7 -> 1.4941834e+08 | G7: =0.997*F7 -> 1.4897008e+08 | H7: =0.997*G7 -> 1.4852317e+08 | I7: =0.997*H7 -> 1.4807761e+08 | J7: =0.997*I7 -> 1.4763337e+08 | K7: =0.997*J7 -> 1.4719047e+08 | ... AQ7: =0.997*AP7 -> 1.3369795e+08
A8: 0-1945 | B8: Denmark | C8: 86408212 | D8: =0.997*C8 -> 86148987 | E8: =0.997*D8 -> 85890540 | F8: =0.997*E8 -> 85632869 | G8: =0.997*F8 -> 85375970 | H8: =0.997*G8 -> 85119842 | I8: =0.997*H8 -> 84864483 | J8: =0.997*I8 -> 84609889 | K8: =0.997*J8 -> 84356060 | ... AQ8: =0.997*AP8 -> 76623388
A9: 0-1945 | B9: Estonia | C9: 11903569 | D9: =0.997*C9 -> 11867858 | E9: =0.997*D9 -> 11832255 | F9: =0.997*E9 -> 11796758 | G9: =0.997*F9 -> 11761368 | H9: =0.997*G9 -> 11726084 | I9: =0.997*H9 -> 11690905 | J9: =0.997*I9 -> 11655833 | K9: =0.997*J9 -> 11620865 | ... AQ9: =0.997*AP9 -> 10555615
A10: 0-1945 | B10: Finland | C10: 72630161 | D10: =0.997*C10 -> 72412271 | E10: =0.997*D10 -> 72195034 | F10: =0.997*E10 -> 71978449 | G10: =0.997*F10 -> 71762513 | H10: =0.997*G10 -> 71547226 | I10: =0.997*H10 -> 71332584 | J10: =0.997*I10 -> 71118586 | K10: =0.997*J10 -> 70905231 | ... AQ10: =0.997*AP10 -> 64405557
A11: 0-1945 | B11: France | C11: 997402420 | D11: =0.997*C11 -> 9.9441021e+08 | E11: =0.997*D11 -> 9.9142698e+08 | F11: =0.997*E11 -> 9.884527e+08 | G11: =0.997*F11 -> 9.8548734e+08 | H11: =0.997*G11 -> 9.8253088e+08 | I11: =0.997*H11 -> 9.7958329e+08 | J11: =0.997*I11 -> 9.7664454e+08 | K11: =0.997*J11 -> 9.737146e+08 | ... AQ11: =0.997*AP11 -> 8.8445705e+08
A12: 0-1945 | B12: Germany | C12: 1162662495 | D12: =0.997*C12 -> 1.1591745e+09 | E12: =0.997*D12 -> 1.155697e+09 | F12: =0.997*E12 -> 1.1522299e+09 | G12: =0.997*F12 -> 1.1487732e+09 | H12: =0.997*G12 -> 1.1453269e+09 | I12: =0.997*H12 -> 1.1418909e+09 | J12: =0.997*I12 -> 1.1384652e+09 | K12: =0.997*J12 -> 1.1350498e+09 | ... AQ12: =0.997*AP12 -> 1.0310032e+09
A13: 0-1945 | B13: Greece | C13: 89919131 | D13: =0.997*C13 -> 89649374 | E13: =0.997*D13 -> 89380425 | F13: =0.997*E13 -> 89112284 | G13: =0.997*F13 -> 88844947 | H13: =0.997*G13 -> 88578413 | I13: =0.997*H13 -> 88312677 | J13: =0.997*I13 -> 88047739 | K13: =0.997*J13 -> 87783596 | ... AQ13: =0.997*AP13 -> 79736732
... A28: 0-1945 | B28: Sweden | C28: 123368769 | D28: =0.997*C28 -> 1.2299866e+08 | E28: =0.997*D28 -> 1.2262967e+08 | F28: =0.997*E28 -> 1.2226178e+08 | G28: =0.997*F28 -> 1.2189499e+08 | H28: =0.997*G28 -> 1.2152931e+08 | I28: =0.997*H28 -> 1.2116472e+08 | J28: =0.997*I28 -> 1.2080123e+08 | K28: =0.997*J28 -> 1.2043882e+08 | ... AQ28: =0.997*AP28 -> 1.0939855e+08
A29: 1946-1969 | B29: Austria | C29: 175505382
A30: 1946-1969 | B30: Belgium | C30: 179280291
A31: 1946-1969 | B31: Bulgaria | C31: 93421183
A32: 1946-1969 | B32: Croatia | C32: 40161976
A33: 1946-1969 | B33: Cyprus | C33: 31223377
A34: 1946-1969 | B34: Czechia | C34: 110282225
A35: 1946-1969 | B35: Denmark | C35: 84591452
A36: 1946-1969 | B36: Estonia | C36: 8178748
A37: 1946-1969 | B37: Finland | C37: 120144375
A38: 1946-1969 | B38: France | C38: 523328214
A39: 1946-1969 | B39: Germany | C39: 2149374638
A40: 1946-1969 | B40: Greece | C40: 135883258
... A163: 2000-2010 | B163: Sweden | C163: 76249781
A164: 2011-now | B164: Austria | C164: 17171583 | D164: =C164+1000000*new_building_eurostat!$L12 -> 26231583 | E164: =D164+1000000*new_building_eurostat!$L12 -> 35291583 | F164: =E164+1000000*new_building_eurostat!$L12 -> 44351583 | G164: =F164+1000000*new_building_eurostat!$L12 -> 53411583 | H164: =G164+1000000*new_building_eurostat!$L12 -> 62471583 | I164: =H164+1000000*new_building_eurostat!$L12 -> 71531583 | J164: =I164+1000000*new_building_eurostat!$L12 -> 80591583 | K164: =J164+1000000*new_building_eurostat!$L12 -> 89651583 | ... AQ164: =AP164+1000000*new_building_eurostat!$L12 -> 379571583 | AS164: =SUM(C164, C137,C110,C83,C56,C29,C2) -> 645587790
A165: 2011-now | B165: Belgium | C165: 30767106 | D165: =C165+1000000*new_building_eurostat!$L13 -> 46507106 | E165: =D165+1000000*new_building_eurostat!$L13 -> 62247106 | F165: =E165+1000000*new_building_eurostat!$L13 -> 77987106 | G165: =F165+1000000*new_building_eurostat!$L13 -> 93727106 | H165: =G165+1000000*new_building_eurostat!$L13 -> 109467106 | I165: =H165+1000000*new_building_eurostat!$L13 -> 125207106 | J165: =I165+1000000*new_building_eurostat!$L13 -> 140947106 | K165: =J165+1000000*new_building_eurostat!$L13 -> 156687106 | ... AQ165: =AP165+1000000*new_building_eurostat!$L13 -> 660367106 | AS165: =SUM(C165, C138,C111,C84,C57,C30,C3) -> 922861673
A166: 2011-now | B166: Bulgaria | C166: 27057324 | D166: =C166+1000000*new_building_eurostat!$L14 -> 35017324 | E166: =D166+1000000*new_building_eurostat!$L14 -> 42977324 | F166: =E166+1000000*new_building_eurostat!$L14 -> 50937324 | G166: =F166+1000000*new_building_eurostat!$L14 -> 58897324 | H166: =G166+1000000*new_building_eurostat!$L14 -> 66857324 | I166: =H166+1000000*new_building_eurostat!$L14 -> 74817324 | J166: =I166+1000000*new_building_eurostat!$L14 -> 82777324 | K166: =J166+1000000*new_building_eurostat!$L14 -> 90737324 | ... AQ166: =AP166+1000000*new_building_eurostat!$L14 -> 345457324 | AS166: =SUM(C166, C139,C112,C85,C58,C31,C4) -> 411076575
A167: 2011-now | B167: Croatia | C167: 18298503 | D167: =C167+1000000*new_building_eurostat!$L15 -> 21738503 | E167: =D167+1000000*new_building_eurostat!$L15 -> 25178503 | F167: =E167+1000000*new_building_eurostat!$L15 -> 28618503 | G167: =F167+1000000*new_building_eurostat!$L15 -> 32058503 | H167: =G167+1000000*new_building_eurostat!$L15 -> 35498503 | I167: =H167+1000000*new_building_eurostat!$L15 -> 38938503 | J167: =I167+1000000*new_building_eurostat!$L15 -> 42378503 | K167: =J167+1000000*new_building_eurostat!$L15 -> 45818503 | ... AQ167: =AP167+1000000*new_building_eurostat!$L15 -> 155898503 | AS167: =SUM(C167, C140,C113,C86,C59,C32,C5) -> 226678535
A168: 2011-now | B168: Cyprus | C168: 10279271 | D168: =C168+1000000*new_building_eurostat!$L16 -> 12759271 | E168: =D168+1000000*new_building_eurostat!$L16 -> 15239271 | F168: =E168+1000000*new_building_eurostat!$L16 -> 17719271 | G168: =F168+1000000*new_building_eurostat!$L16 -> 20199271 | H168: =G168+1000000*new_building_eurostat!$L16 -> 22679271 | I168: =H168+1000000*new_building_eurostat!$L16 -> 25159271 | J168: =I168+1000000*new_building_eurostat!$L16 -> 27639271 | K168: =J168+1000000*new_building_eurostat!$L16 -> 30119271 | ... AQ168: =AP168+1000000*new_building_eurostat!$L16 -> 109479271 | AS168: =SUM(C168, C141,C114,C87,C60,C33,C6) -> 112474037
A169: 2011-now | B169: Czechia | C169: 40695491 | D169: =C169+1000000*new_building_eurostat!$L17 -> 48275491 | E169: =D169+1000000*new_building_eurostat!$L17 -> 55855491 | F169: =E169+1000000*new_building_eurostat!$L17 -> 63435491 | G169: =F169+1000000*new_building_eurostat!$L17 -> 71015491 | H169: =G169+1000000*new_building_eurostat!$L17 -> 78595491 | I169: =H169+1000000*new_building_eurostat!$L17 -> 86175491 | J169: =I169+1000000*new_building_eurostat!$L17 -> 93755491 | K169: =J169+1000000*new_building_eurostat!$L17 -> 101335491 | ... AQ169: =AP169+1000000*new_building_eurostat!$L17 -> 343895491 | AS169: =SUM(C169, C142,C115,C88,C61,C34,C7) -> 660472107
A170: 2011-now | B170: Denmark | C170: 43419261 | D170: =C170+1000000*new_building_eurostat!$L18 -> 51039261 | E170: =D170+1000000*new_building_eurostat!$L18 -> 58659261 | F170: =E170+1000000*new_building_eurostat!$L18 -> 66279261 | G170: =F170+1000000*new_building_eurostat!$L18 -> 73899261 | H170: =G170+1000000*new_building_eurostat!$L18 -> 81519261 | I170: =H170+1000000*new_building_eurostat!$L18 -> 89139261 | J170: =I170+1000000*new_building_eurostat!$L18 -> 96759261 | K170: =J170+1000000*new_building_eurostat!$L18 -> 104379261 | ... AQ170: =AP170+1000000*new_building_eurostat!$L18 -> 348219261 | AS170: =SUM(C170, C143,C116,C89,C62,C35,C8) -> 485517559
A171: 2011-now | B171: Estonia | C171: 3904904 | D171: =C171+1000000*new_building_eurostat!$L19 -> 5544904 | E171: =D171+1000000*new_building_eurostat!$L19 -> 7184904 | F171: =E171+1000000*new_building_eurostat!$L19 -> 8824904 | G171: =F171+1000000*new_building_eurostat!$L19 -> 10464904 | H171: =G171+1000000*new_building_eurostat!$L19 -> 12104904 | I171: =H171+1000000*new_building_eurostat!$L19 -> 13744904 | J171: =I171+1000000*new_building_eurostat!$L19 -> 15384904 | K171: =J171+1000000*new_building_eurostat!$L19 -> 17024904 | ... AQ171: =AP171+1000000*new_building_eurostat!$L19 -> 69504904 | AS171: =SUM(C171, C144,C117,C90,C63,C36,C9) -> 44472579
A172: 2011-now | B172: Finland | C172: 13249956 | D172: =C172+1000000*new_building_eurostat!$L20 -> 19729956 | E172: =D172+1000000*new_building_eurostat!$L20 -> 26209956 | F172: =E172+1000000*new_building_eurostat!$L20 -> 32689956 | G172: =F172+1000000*new_building_eurostat!$L20 -> 39169956 | H172: =G172+1000000*new_building_eurostat!$L20 -> 45649956 | I172: =H172+1000000*new_building_eurostat!$L20 -> 52129956 | J172: =I172+1000000*new_building_eurostat!$L20 -> 58609956 | K172: =J172+1000000*new_building_eurostat!$L20 -> 65089956 | ... AQ172: =AP172+1000000*new_building_eurostat!$L20 -> 272449956 | AS172: =SUM(C172, C145,C118,C91,C64,C37,C10) -> 516777934
A173: 2011-now | B173: France | C173: 424818667 | D173: =C173+1000000*new_building_eurostat!$L21 -> 495998667 | E173: =D173+1000000*new_building_eurostat!$L21 -> 567178667 | F173: =E173+1000000*new_building_eurostat!$L21 -> 638358667 | G173: =F173+1000000*new_building_eurostat!$L21 -> 709538667 | H173: =G173+1000000*new_building_eurostat!$L21 -> 780718667 | I173: =H173+1000000*new_building_eurostat!$L21 -> 851898667 | J173: =I173+1000000*new_building_eurostat!$L21 -> 923078667 | K173: =J173+1000000*new_building_eurostat!$L21 -> 994258667 | ... AQ173: =AP173+1000000*new_building_eurostat!$L21 -> 3272018667 | AS173: =SUM(C173, C146,C119,C92,C65,C38,C11) -> 4129205964
A174: 2011-now | B174: Germany | C174: 512800262 | D174: =C174+1000000*new_building_eurostat!$L22 -> 570480262 | E174: =D174+1000000*new_building_eurostat!$L22 -> 628160262 | F174: =E174+1000000*new_building_eurostat!$L22 -> 685840262 | G174: =F174+1000000*new_building_eurostat!$L22 -> 743520262 | H174: =G174+1000000*new_building_eurostat!$L22 -> 801200262 | I174: =H174+1000000*new_building_eurostat!$L22 -> 858880262 | J174: =I174+1000000*new_building_eurostat!$L22 -> 916560262 | K174: =J174+1000000*new_building_eurostat!$L22 -> 974240262 | ... AQ174: =AP174+1000000*new_building_eurostat!$L22 -> 2820000262 | AS174: =SUM(C174, C147,C120,C93,C66,C39,C12) -> 7315633330
A175: 2011-now | B175: Greece | C175: 32706209 | D175: =C175+1000000*new_building_eurostat!$L23 -> 36906209 | E175: =D175+1000000*new_building_eurostat!$L23 -> 41106209 | F175: =E175+1000000*new_building_eurostat!$L23 -> 45306209 | G175: =F175+1000000*new_building_eurostat!$L23 -> 49506209 | H175: =G175+1000000*new_building_eurostat!$L23 -> 53706209 | I175: =H175+1000000*new_building_eurostat!$L23 -> 57906209 | J175: =I175+1000000*new_building_eurostat!$L23 -> 62106209 | K175: =J175+1000000*new_building_eurostat!$L23 -> 66306209 | ... AQ175: =AP175+1000000*new_building_eurostat!$L23 -> 200706209 | AS175: =SUM(C175, C148,C121,C94,C67,C40,C13) -> 669797794
... A183: 2011-now | B183: Netherlands | C183: 49505370 | D183: =C183+1000000*new_building_eurostat!$L31 -> 68465370 | E183: =D183+1000000*new_building_eurostat!$L31 -> 87425370 | F183: =E183+1000000*new_building_eurostat!$L31 -> 106385370 | G183: =F183+1000000*new_building_eurostat!$L31 -> 125345370 | H183: =G183+1000000*new_building_eurostat!$L31 -> 144305370 | I183: =H183+1000000*new_building_eurostat!$L31 -> 163265370 | J183: =I183+1000000*new_building_eurostat!$L31 -> 182225370 | K183: =J183+1000000*new_building_eurostat!$L31 -> 201185370 | ... AQ183: =AP183+1000000*new_building_eurostat!$L31 -> 807905370 | AS183: =SUM(C183, C156,C129,C102,C75,C48,C21) -> 1124017845
...
