Workbook

Sheet Documentation
A1: Sources
B2: ICIS | C2: Data set scrapt from the web page in the graph "European Data Centre Demand by Country 2024–2035 (TWh)"
B3: EnBW Zukunftsbild 2026 | C3: Heat Pump Values from 2024 to 2060 for 4 different scenarios
B7: · German Values from EnBW Model!
B8: · Other countries From ICIS (Zotero: data_centers_2035)
B9: · Luxemburg missing:
B10: o 16.5 MW capacity of data centers in 2023 (Zotero: LU_data_center_capa), which is about 0.1 TWh electricity demand yearly, with capacity factor of 0.6 (Zotero: )
B11: o EU data center demand growth by almost 150% by 2035 (Zotero: EMBER_data_centers), so this scaling factor is also used for Luxembourg! And the values from 2025 to 2035 are used linearly.
B12: · ICIS Data only up to 2035 à KKO
B13: o For 2036 to 2060 in KKO, for each year, the same growth rate of Germany is assumed in relation to 2035 value. For example:
B14: Austria_KKO2060 = Austria_KKO2035 * (Germany_KKO2060/Germany_KKO2060)
B16: · For other scenarios (KVE, VWE, VNI):
B17: o First calculating the scale of German KKO scenario to each scenario for years 2026 to 2035. And use this scale factor for other countries for each year. For example:
B18: Austria_VNI2026 = Austria_KKO2026 (Germany_VNI2026/Germany_KKO2026)
B20: o Then using same approach of 2036 to 2060: taking the growth rate of Germany in that scenario relative to 2035.
B21: Austria_VNI2060 = Austria_VNI2035 * (Germany_VNI2060/Germany_VNI2060)

Sheet ICIS
A1: European Data Centre Demand by Country 2024–2035 (TWh)
A2: Source: ICIS – Data Centres Hungry for Power (via Infogram chart)
A3: Country | B3: 2024 | C3: 2025 | D3: 2026 | E3: 2027 | F3: 2028 | G3: 2029 | H3: 2030 | I3: 2031 | J3: 2032 | K3: 2033 | L3: 2034 | M3: 2035 | N3: CAGR 2024–2035
A4: Germany | B4: 20.6 | C4: 22.4 | D4: 24.3 | E4: 26.3 | F4: 28.3 | G4: 30.5 | H4: 32.7 | I4: 34.9 | J4: 37.2 | K4: 39.5 | L4: 41.7 | M4: 43.9 | N4: =(M4/B4)^(1/11)-1 -> 0.07120473
A5: France | B5: 11 | C5: 12.2 | D5: 13.4 | E5: 14.7 | F5: 16.1 | G5: 17.5 | H5: 19 | I5: 20.5 | J5: 22.1 | K5: 23.7 | L5: 25.2 | M5: 26.8 | N5: =(M5/B5)^(1/11)-1 -> 0.08432226
A6: United Kingdom | B6: 12.6 | C6: 13.4 | D6: 14.3 | E6: 15.2 | F6: 16.1 | G6: 17.1 | H6: 18.1 | I6: 19.1 | J6: 20.1 | K6: 21.1 | L6: 22.1 | M6: 23.1 | N6: =(M6/B6)^(1/11)-1 -> 0.056649713
A7: Norway | B7: 3.9 | C7: 4.9 | D7: 6 | E7: 7.1 | F7: 8.2 | G7: 9.4 | H7: 10.6 | I7: 11.9 | J7: 13.1 | K7: 14.3 | L7: 15.5 | M7: 16.7 | N7: =(M7/B7)^(1/11)-1 -> 0.14136065
A8: Sweden | B8: 2.9 | C8: 3.8 | D8: 4.8 | E8: 5.8 | F8: 6.8 | G8: 7.9 | H8: 9.1 | I8: 10.2 | J8: 11.4 | K8: 12.6 | L8: 13.7 | M8: 14.9 | N8: =(M8/B8)^(1/11)-1 -> 0.1604251
A9: Ireland | B9: 6.8 | C9: 7.5 | D9: 8.1 | E9: 8.8 | F9: 9.4 | G9: 10.1 | H9: 10.7 | I9: 11.4 | J9: 12 | K9: 12.6 | L9: 13.1 | M9: 13.6 | N9: =(M9/B9)^(1/11)-1 -> 0.065041089
A10: Netherlands | B10: 8.4 | C10: 8.8 | D10: 9.3 | E10: 9.7 | F10: 10.2 | G10: 10.7 | H10: 11.2 | I10: 11.7 | J10: 12.2 | K10: 12.7 | L10: 13.1 | M10: 13.6 | N10: =(M10/B10)^(1/11)-1 -> 0.044776997
A11: Spain | B11: 5.3 | C11: 5.8 | D11: 6.4 | E11: 7 | F11: 7.6 | G11: 8.3 | H11: 9.1 | I11: 9.8 | J11: 10.6 | K11: 11.3 | L11: 12.1 | M11: 12.9 | N11: =(M11/B11)^(1/11)-1 -> 0.084225058
A12: Italy | B12: 3.6 | C12: 4.1 | D12: 4.6 | E12: 5.1 | F12: 5.7 | G12: 6.3 | H12: 7 | I12: 7.7 | J12: 8.4 | K12: 9.2 | L12: 9.9 | M12: 10.7 | N12: =(M12/B12)^(1/11)-1 -> 0.1040974
A13: Denmark | B13: 2 | C13: 2.6 | D13: 3.3 | E13: 4 | F13: 4.7 | G13: 5.4 | H13: 6.1 | I13: 6.8 | J13: 7.5 | K13: 8.2 | L13: 8.9 | M13: 9.5 | N13: =(M13/B13)^(1/11)-1 -> 0.15217275
A14: Finland | B14: 1.5 | C14: 1.8 | D14: 2.2 | E14: 2.6 | F14: 3 | G14: 3.5 | H14: 3.9 | I14: 4.4 | J14: 4.9 | K14: 5.3 | L14: 5.8 | M14: 6.3 | N14: =(M14/B14)^(1/11)-1 -> 0.13935491
A15: Switzerland | B15: 2.4 | C15: 2.6 | D15: 2.9 | E15: 3.2 | F15: 3.5 | G15: 3.8 | H15: 4.1 | I15: 4.5 | J15: 4.8 | K15: 5.1 | L15: 5.4 | M15: 5.7 | N15: =(M15/B15)^(1/11)-1 -> 0.081810613
... A30: Latvia | B30: 0.3 | C30: 0.4 | D30: 0.4 | E30: 0.5 | F30: 0.5 | G30: 0.5 | H30: 0.6 | I30: 0.6 | J30: 0.7 | K30: 0.7 | L30: 0.8 | M30: 0.8 | N30: =(M30/B30)^(1/11)-1 -> 0.093262446
A31: Cyprus | B31: 0 | C31: 0.1 | D31: 0.1 | E31: 0.1 | F31: 0.1 | G31: 0.1 | H31: 0.1 | I31: 0.2 | J31: 0.2 | K31: 0.2 | L31: 0.2 | M31: 0.2 | N31: =IFERROR((M31/B31)^(1/11)-1,"n/a") -> n/a
A32: TOTAL | B32: =SUM(B4:B31) -> 96 | C32: =SUM(C4:C31) -> 106.9 | D32: =SUM(D4:D31) -> 118.2 | E32: =SUM(E4:E31) -> 129.9 | F32: =SUM(F4:F31) -> 141.8 | G32: =SUM(G4:G31) -> 154.8 | H32: =SUM(H4:H31) -> 168.1 | I32: =SUM(I4:I31) -> 181.5 | ... M32: =SUM(M4:M31) -> 235.6 | N32: =(M32/B32)^(1/11)-1 -> 0.085040186

Sheet Historical_2010_2024
A1: country | B1: 2010 | C1: 2011 | D1: 2012 | E1: 2013 | F1: 2014 | G1: 2015 | H1: 2016 | I1: 2017 | J1: 2018 | K1: 2019 | L1: 2020 | M1: 2021 | N1: 2022 | O1: 2023 | P1: 2024 | Q1: yearly Difference
A2: Germany | B2: =C2-$Q$2 -> 5.2 | C2: =D2-$Q$2 -> 6.3 | D2: =E2-$Q$2 -> 7.4 | E2: =F2-$Q$2 -> 8.5 | F2: =G2-$Q$2 -> 9.6 | G2: =H2-$Q$2 -> 10.7 | H2: =I2-$Q$2 -> 11.8 | I2: =J2-$Q$2 -> 12.9 | J2: 14 | K2: =J2+$Q$2 -> 15.1 | L2: =K2+$Q$2 -> 16.2 | M2: =L2+$Q$2 -> 17.3 | N2: =M2+$Q$2 -> 18.4 | O2: =N2+$Q$2 -> 19.5 | P2: 20.6 | Q2: =($P$2-$J$2)/(P1-J1) -> 1.1
A3: France | B3: 0 | C3: 0 | D3: 0 | E3: 0 | F3: 0 | G3: 0 | H3: 0 | I3: =J3-$Q$3 -> 0.85 | J3: =K3-$Q$3 -> 2.3 | K3: =L3-$Q$3 -> 3.75 | L3: 5.2 | M3: =L3+$Q$3 -> 6.65 | N3: =M3+$Q$3 -> 8.1 | O3: =N3+$Q$3 -> 9.55 | P3: 11 | Q3: =(P3-L3)/(P1-L1) -> 1.45
A4: Norway | B4: 0 | C4: 0 | D4: 0 | E4: 0 | F4: 0 | G4: 0 | H4: 0 | I4: =H4+$Q$4 -> 0.4875 | J4: =I4+$Q$4 -> 0.975 | K4: =J4+$Q$4 -> 1.4625 | L4: =K4+$Q$4 -> 1.95 | M4: =L4+$Q$4 -> 2.4375 | N4: =M4+$Q$4 -> 2.925 | O4: =N4+$Q$4 -> 3.4125 | P4: 3.9 | Q4: =(P4-H4)/($P$1-H1) -> 0.4875
A5: Sweden | B5: =C5-$Q$5 -> 1.15 | C5: =D5-$Q$5 -> 1.275 | D5: =E5-$Q$5 -> 1.4 | E5: =F5-$Q$5 -> 1.525 | F5: =G5-$Q$5 -> 1.65 | G5: =H5-$Q$5 -> 1.775 | H5: =I5-$Q$5 -> 1.9 | I5: =J5-$Q$5 -> 2.025 | ... K5: =L5-$Q$5 -> 2.275 | L5: 2.4 | M5: =L5+$Q$5 -> 2.525 | N5: =M5+$Q$5 -> 2.65 | O5: =N5+$Q$5 -> 2.775 | P5: 2.9 | Q5: =(P5-L5)/($P$1-L1) -> 0.125
A6: Ireland | B6: 0 | C6: 0 | D6: 0 | E6: 0 | F6: 0 | G6: 0 | H6: 0 | I6: =J6-$Q$6 -> 0.78 | J6: =K6-$Q$6 -> 1.64 | K6: 2.5 | L6: =K6+$Q$6 -> 3.36 | M6: =L6+$Q$6 -> 4.22 | N6: =M6+$Q$6 -> 5.08 | O6: =N6+$Q$6 -> 5.94 | P6: 6.8 | Q6: =(P6-K6)/($P$1-K1) -> 0.86
A7: Netherlands | B7: 0 | C7: 0 | D7: 0 | E7: 0 | F7: 0 | G7: 0 | H7: =I7-$Q$7 -> 0.62857143 | I7: 1.6 | J7: =I7+$Q$7 -> 2.5714286 | K7: =J7+$Q$7 -> 3.5428571 | L7: =K7+$Q$7 -> 4.5142857 | M7: =L7+$Q$7 -> 5.4857143 | N7: =M7+$Q$7 -> 6.4571429 | O7: =N7+$Q$7 -> 7.4285714 | P7: 8.4 | Q7: =(P7-I7)/($P$1-I1) -> 0.97142857
A8: Spain | B8: 0 | C8: 0 | D8: 0 | E8: 0 | F8: 0 | G8: 0 | H8: 0 | I8: =H8+$Q$8 -> 0.6625 | J8: =I8+$Q$8 -> 1.325 | K8: =J8+$Q$8 -> 1.9875 | L8: =K8+$Q$8 -> 2.65 | M8: =L8+$Q$8 -> 3.3125 | N8: =M8+$Q$8 -> 3.975 | O8: =N8+$Q$8 -> 4.6375 | P8: 5.3 | Q8: =(P8-H8)/($P$1-H1) -> 0.6625
A9: Italy | B9: 0 | C9: 0 | D9: 0 | E9: 0 | F9: 0 | G9: 0 | H9: 0 | I9: =H9+$Q$9 -> 0.45 | J9: =I9+$Q$9 -> 0.9 | K9: =J9+$Q$9 -> 1.35 | L9: =K9+$Q$9 -> 1.8 | M9: =L9+$Q$9 -> 2.25 | N9: =M9+$Q$9 -> 2.7 | O9: =N9+$Q$9 -> 3.15 | P9: 3.6 | Q9: =(P9-H9)/($P$1-H1) -> 0.45
A10: Denmark | B10: 0 | C10: 0 | D10: 0 | E10: 0 | F10: 0 | G10: 0 | H10: 0 | I10: =J10-$Q$10 -> 0.04 | J10: =K10-$Q$10 -> 0.32 | K10: =L10-$Q$10 -> 0.6 | L10: 0.88 | M10: =L10+$Q$10 -> 1.16 | N10: =M10+$Q$10 -> 1.44 | O10: =N10+$Q$10 -> 1.72 | P10: 2 | Q10: =(P10-L10)/($P$1-L1) -> 0.28
A11: Finland | B11: 0 | C11: 0 | D11: 0 | E11: 0 | F11: 0 | G11: 0 | H11: 0 | I11: =J11-$Q$11 -> 0.041666667 | J11: 0.25 | K11: =J11+$Q$11 -> 0.45833333 | L11: =K11+$Q$11 -> 0.66666667 | M11: =L11+$Q$11 -> 0.875 | N11: =M11+$Q$11 -> 1.0833333 | O11: =N11+$Q$11 -> 1.2916667 | P11: 1.5 | Q11: =(P11-J11)/($P$1-J1) -> 0.20833333
A12: Belgium | B12: 0 | C12: 0 | D12: 0 | E12: 0 | F12: 0 | G12: 0 | H12: 0 | I12: 0 | J12: 0 | K12: 0 | L12: 0 | M12: 0.38 | N12: =M12+$Q$12 -> 0.98666667 | O12: =N12+$Q$12 -> 1.5933333 | P12: 2.2 | Q12: =(P12-M12)/($P$1-M1) -> 0.60666667
A13: Poland | B13: 0 | C13: 0 | D13: 0 | E13: 0 | F13: 0 | G13: 0 | H13: 0 | I13: =H13+$Q13 -> 0.3375 | J13: =I13+$Q13 -> 0.675 | K13: =J13+$Q13 -> 1.0125 | L13: =K13+$Q13 -> 1.35 | M13: =L13+$Q13 -> 1.6875 | N13: =M13+$Q13 -> 2.025 | O13: =N13+$Q13 -> 2.3625 | P13: 2.7 | Q13: =(P13-H13)/($P$1-H1) -> 0.3375
A14: Austria | B14: 0 | C14: 0 | D14: 0 | E14: 0 | F14: 0 | G14: 0 | H14: 0 | I14: =H14+$Q14 -> 0.15 | J14: =I14+$Q14 -> 0.3 | K14: =J14+$Q14 -> 0.45 | L14: =K14+$Q14 -> 0.6 | M14: =L14+$Q14 -> 0.75 | N14: =M14+$Q14 -> 0.9 | O14: =N14+$Q14 -> 1.05 | P14: 1.2 | Q14: =(P14-H14)/($P$1-$H$1) -> 0.15
A15: Portugal | B15: 0 | C15: 0 | D15: 0 | E15: 0 | F15: 0 | G15: 0 | H15: 0 | I15: =H15+$Q15 -> 0.1375 | J15: =I15+$Q15 -> 0.275 | K15: =J15+$Q15 -> 0.4125 | L15: =K15+$Q15 -> 0.55 | M15: =L15+$Q15 -> 0.6875 | N15: =M15+$Q15 -> 0.825 | O15: =N15+$Q15 -> 0.9625 | P15: 1.1 | Q15: =(P15-H15)/($P$1-$H$1) -> 0.1375
A16: Czechia | B16: 0 | C16: 0 | D16: 0 | E16: 0 | F16: 0 | G16: 0 | H16: 0 | I16: =H16+$Q16 -> 0.1625 | J16: =I16+$Q16 -> 0.325 | K16: =J16+$Q16 -> 0.4875 | L16: =K16+$Q16 -> 0.65 | M16: =L16+$Q16 -> 0.8125 | N16: =M16+$Q16 -> 0.975 | O16: =N16+$Q16 -> 1.1375 | P16: 1.3 | Q16: =(P16-H16)/($P$1-$H$1) -> 0.1625
A17: Romania | B17: 0 | C17: 0 | D17: 0 | E17: 0 | F17: 0 | G17: 0 | H17: 0 | I17: =H17+$Q17 -> 0.2 | J17: =I17+$Q17 -> 0.4 | K17: =J17+$Q17 -> 0.6 | L17: =K17+$Q17 -> 0.8 | M17: =L17+$Q17 -> 1 | N17: =M17+$Q17 -> 1.2 | O17: =N17+$Q17 -> 1.4 | P17: 1.6 | Q17: =(P17-H17)/($P$1-$H$1) -> 0.2
A18: Hungary | B18: 0 | C18: 0 | D18: 0 | E18: 0 | F18: 0 | G18: 0 | H18: 0 | I18: 0 | J18: 0 | K18: 0 | L18: 0 | M18: 0 | N18: 0 | O18: 0 | P18: 0.5
A19: Bulgaria | B19: 0 | C19: 0 | D19: 0 | E19: 0 | F19: 0 | G19: 0 | H19: 0 | I19: 0 | J19: 0 | K19: 0 | L19: 0 | M19: 0 | N19: 0 | O19: 0 | P19: 1
A20: Slovakia | B20: 0 | C20: 0 | D20: 0 | E20: 0 | F20: 0 | G20: 0 | H20: 0 | I20: 0 | J20: 0 | K20: 0 | L20: 0 | M20: 0 | N20: 0 | O20: 0 | P20: 0.5
A21: Greece | B21: 0 | C21: 0 | D21: 0 | E21: 0 | F21: 0 | G21: 0 | H21: 0 | I21: 0 | J21: 0 | K21: 0 | L21: 0 | M21: 0 | N21: 0 | O21: 0 | P21: 0.5
A22: Croatia | B22: 0 | C22: 0 | D22: 0 | E22: 0 | F22: 0 | G22: 0 | H22: 0 | I22: 0 | J22: 0 | K22: 0 | L22: 0 | M22: 0 | N22: 0 | O22: 0 | P22: 0.6
A23: Lithuania | B23: 0 | C23: 0 | D23: 0 | E23: 0 | F23: 0 | G23: 0 | H23: 0 | I23: 0 | J23: 0 | K23: 0 | L23: 0 | M23: 0 | N23: 0 | O23: 0 | P23: 0.6
A24: Slovenia | B24: 0 | C24: 0 | D24: 0 | E24: 0 | F24: 0 | G24: 0 | H24: 0 | I24: 0 | J24: 0 | K24: 0 | L24: 0 | M24: 0 | N24: 0 | O24: 0 | P24: 0.5
A25: Estonia | B25: 0 | C25: 0 | D25: 0 | E25: 0 | F25: 0 | G25: 0 | H25: 0 | I25: 0 | J25: 0 | K25: 0 | L25: 0 | M25: 0 | N25: 0 | O25: 0 | P25: 0.4
A26: Latvia | B26: 0 | C26: 0 | D26: 0 | E26: 0 | F26: 0 | G26: 0 | H26: 0 | I26: 0 | J26: 0 | K26: 0 | L26: 0 | M26: 0 | N26: 0 | O26: 0 | P26: 0.3
A27: Luxembourg | B27: 0 | C27: 0 | D27: 0 | E27: 0 | F27: 0 | G27: 0 | H27: 0 | I27: 0 | J27: 0 | K27: 0 | L27: 0 | M27: 0 | N27: 0 | O27: 0 | P27: 0
A30: Black Values From ICIS
A31: Green Values from JRC
A32: Grey Values calculated linearly

Sheet ds_model_results
A1: country | B1: scenario | C1: 2024 | D1: 2025 | E1: 2026 | F1: 2027 | G1: 2028 | H1: 2029 | I1: 2030 | J1: 2031 | K1: 2032 | L1: 2033 | M1: 2034 | N1: 2035 | O1: 2036 | P1: 2037 | Q1: 2038 | R1: 2039 | S1: 2040 | T1: 2041 | U1: 2042 | V1: 2043 | W1: 2044 | X1: 2045 | Y1: 2046 | Z1: 2047 | AA1: 2048 | AB1: 2049 | AC1: 2050 | AD1: 2051 | AE1: 2052 | AF1: 2053 | AG1: 2054 | AH1: 2055 | AI1: 2056 | AJ1: 2057 | AK1: 2058 | AL1: 2059 | AM1: 2060
A2: Germany | B2: KKO | C2: ='input_EnBW Model 2026'!C2 -> 20.028514 | D2: ='input_EnBW Model 2026'!D2 -> 21.630553 | E2: ='input_EnBW Model 2026'!E2 -> 23.346581 | F2: ='input_EnBW Model 2026'!F2 -> 25.182703 | G2: ='input_EnBW Model 2026'!G2 -> 27.145034 | H2: ='input_EnBW Model 2026'!H2 -> 29.239628 | I2: ='input_EnBW Model 2026'!I2 -> 31.472397 | J2: ='input_EnBW Model 2026'!J2 -> 33.489886 | ... AM2: ='input_EnBW Model 2026'!AM2 -> 81.025621
A3: France | B3: KKO | C3: 11 | D3: 12.2 | E3: 13.4 | F3: 14.7 | G3: 16.1 | H3: 17.5 | I3: 19 | J3: 20.5 | K3: 22.1 | L3: 23.7 | M3: 25.2 | N3: 26.8 | O3: =$N3*O$2/$N$2 -> 28.608168 | P3: =$N3*P$2/$N$2 -> 30.538169 | Q3: =$N3*Q$2/$N$2 -> 32.598203 | R3: =$N3*R$2/$N$2 -> 34.797017 | S3: =$N3*S$2/$N$2 -> 37.143949 | T3: =$N3*T$2/$N$2 -> 38.627562 | U3: =$N3*U$2/$N$2 -> 40.170221 | V3: =$N3*V$2/$N$2 -> 41.774267 | ... AM3: =$N3*AM$2/$N$2 -> 50.584974
A4: Norway | B4: KKO | C4: 3.9 | D4: 4.9 | E4: 6 | F4: 7.1 | G4: 8.2 | H4: 9.4 | I4: 10.6 | J4: 11.9 | K4: 13.1 | L4: 14.3 | M4: 15.5 | N4: 16.7 | O4: =$N4*O$2/$N$2 -> 17.826731 | P4: =$N4*P$2/$N$2 -> 19.029382 | Q4: =$N4*Q$2/$N$2 -> 20.313059 | R4: =$N4*R$2/$N$2 -> 21.683216 | S4: =$N4*S$2/$N$2 -> 23.14567 | T4: =$N4*T$2/$N$2 -> 24.07016 | U4: =$N4*U$2/$N$2 -> 25.031444 | V4: =$N4*V$2/$N$2 -> 26.03098 | ... AM4: =$N4*AM$2/$N$2 -> 31.521234
A5: Sweden | B5: KKO | C5: 2.9 | D5: 3.8 | E5: 4.8 | F5: 5.8 | G5: 6.8 | H5: 7.9 | I5: 9.1 | J5: 10.2 | K5: 11.4 | L5: 12.6 | M5: 13.7 | N5: 14.9 | O5: =$N5*O$2/$N$2 -> 15.905287 | P5: =$N5*P$2/$N$2 -> 16.978311 | Q5: =$N5*Q$2/$N$2 -> 18.123628 | R5: =$N5*R$2/$N$2 -> 19.346103 | S5: =$N5*S$2/$N$2 -> 20.650927 | T5: =$N5*T$2/$N$2 -> 21.475771 | U5: =$N5*U$2/$N$2 -> 22.333444 | V5: =$N5*V$2/$N$2 -> 23.225246 | ... AM5: =$N5*AM$2/$N$2 -> 28.123735
A6: Ireland | B6: KKO | C6: 6.8 | D6: 7.5 | E6: 8.1 | F6: 8.8 | G6: 9.4 | H6: 10.1 | I6: 10.7 | J6: 11.4 | K6: 12 | L6: 12.6 | M6: 13.1 | N6: 13.6 | O6: =$N6*O$2/$N$2 -> 14.517578 | P6: =$N6*P$2/$N$2 -> 15.496982 | Q6: =$N6*Q$2/$N$2 -> 16.542372 | R6: =$N6*R$2/$N$2 -> 17.658188 | S6: =$N6*S$2/$N$2 -> 18.849168 | T6: =$N6*T$2/$N$2 -> 19.602046 | U6: =$N6*U$2/$N$2 -> 20.384888 | V6: =$N6*V$2/$N$2 -> 21.198882 | ... AM6: =$N6*AM$2/$N$2 -> 25.669987
A7: Netherlands | B7: KKO | C7: 8.4 | D7: 8.8 | E7: 9.3 | F7: 9.7 | G7: 10.2 | H7: 10.7 | I7: 11.2 | J7: 11.7 | K7: 12.2 | L7: 12.7 | M7: 13.1 | N7: 13.6 | O7: =$N7*O$2/$N$2 -> 14.517578 | P7: =$N7*P$2/$N$2 -> 15.496982 | Q7: =$N7*Q$2/$N$2 -> 16.542372 | R7: =$N7*R$2/$N$2 -> 17.658188 | S7: =$N7*S$2/$N$2 -> 18.849168 | T7: =$N7*T$2/$N$2 -> 19.602046 | U7: =$N7*U$2/$N$2 -> 20.384888 | V7: =$N7*V$2/$N$2 -> 21.198882 | ... AM7: =$N7*AM$2/$N$2 -> 25.669987
A8: Spain | B8: KKO | C8: 5.3 | D8: 5.8 | E8: 6.4 | F8: 7 | G8: 7.6 | H8: 8.3 | I8: 9.1 | J8: 9.8 | K8: 10.6 | L8: 11.3 | M8: 12.1 | N8: 12.9 | O8: =$N8*O$2/$N$2 -> 13.770349 | P8: =$N8*P$2/$N$2 -> 14.699343 | Q8: =$N8*Q$2/$N$2 -> 15.690926 | R8: =$N8*R$2/$N$2 -> 16.749311 | S8: =$N8*S$2/$N$2 -> 17.878991 | T8: =$N8*T$2/$N$2 -> 18.593118 | U8: =$N8*U$2/$N$2 -> 19.335666 | V8: =$N8*V$2/$N$2 -> 20.107763 | ... AM8: =$N8*AM$2/$N$2 -> 24.348737
A9: Italy | B9: KKO | C9: 3.6 | D9: 4.1 | E9: 4.6 | F9: 5.1 | G9: 5.7 | H9: 6.3 | I9: 7 | J9: 7.7 | K9: 8.4 | L9: 9.2 | M9: 9.9 | N9: 10.7 | O9: =$N9*O$2/$N$2 -> 11.421918 | P9: =$N9*P$2/$N$2 -> 12.192478 | Q9: =$N9*Q$2/$N$2 -> 13.014954 | R9: =$N9*R$2/$N$2 -> 13.892839 | S9: =$N9*S$2/$N$2 -> 14.82986 | T9: =$N9*T$2/$N$2 -> 15.422198 | U9: =$N9*U$2/$N$2 -> 16.038111 | V9: =$N9*V$2/$N$2 -> 16.678532 | ... AM9: =$N9*AM$2/$N$2 -> 20.19624
A10: Denmark | B10: KKO | C10: 2 | D10: 2.6 | E10: 3.3 | F10: 4 | G10: 4.7 | H10: 5.4 | I10: 6.1 | J10: 6.8 | K10: 7.5 | L10: 8.2 | M10: 8.9 | N10: 9.5 | O10: =$N10*O$2/$N$2 -> 10.140955 | P10: =$N10*P$2/$N$2 -> 10.825097 | Q10: =$N10*Q$2/$N$2 -> 11.555333 | R10: =$N10*R$2/$N$2 -> 12.334764 | S10: =$N10*S$2/$N$2 -> 13.166699 | T10: =$N10*T$2/$N$2 -> 13.692606 | U10: =$N10*U$2/$N$2 -> 14.239444 | V10: =$N10*V$2/$N$2 -> 14.808042 | ... AM10: =$N10*AM$2/$N$2 -> 17.931241
A11: Finland | B11: KKO | C11: 1.5 | D11: 1.8 | E11: 2.2 | F11: 2.6 | G11: 3 | H11: 3.5 | I11: 3.9 | J11: 4.4 | K11: 4.9 | L11: 5.3 | M11: 5.8 | N11: 6.3 | O11: =$N11*O$2/$N$2 -> 6.7250544 | P11: =$N11*P$2/$N$2 -> 7.1787488 | Q11: =$N11*Q$2/$N$2 -> 7.6630104 | R11: =$N11*R$2/$N$2 -> 8.1798958 | S11: =$N11*S$2/$N$2 -> 8.7316001 | T11: =$N11*T$2/$N$2 -> 9.0803597 | U11: =$N11*U$2/$N$2 -> 9.4429997 | V11: =$N11*V$2/$N$2 -> 9.8200703 | ... AM11: =$N11*AM$2/$N$2 -> 11.891244
A12: Belgium | B12: KKO | C12: 2.2 | D12: 2.5 | E12: 2.7 | F12: 3 | G12: 3.2 | H12: 3.5 | I12: 3.8 | J12: 4.1 | K12: 4.4 | L12: 4.7 | M12: 5 | N12: 5.4 | O12: =$N12*O$2/$N$2 -> 5.7643323 | P12: =$N12*P$2/$N$2 -> 6.1532133 | Q12: =$N12*Q$2/$N$2 -> 6.5682946 | R12: =$N12*R$2/$N$2 -> 7.0113393 | S12: =$N12*S$2/$N$2 -> 7.4842286 | T12: =$N12*T$2/$N$2 -> 7.7831655 | U12: =$N12*U$2/$N$2 -> 8.0939997 | V12: =$N12*V$2/$N$2 -> 8.4172031 | ... AM12: =$N12*AM$2/$N$2 -> 10.192495
A13: Poland | B13: KKO | C13: 2.7 | D13: 2.9 | E13: 3 | F13: 3.2 | G13: 3.4 | H13: 3.5 | I13: 3.7 | J13: 3.9 | K13: 4.2 | L13: 4.4 | M13: 4.6 | N13: 4.8 | O13: =$N13*O$2/$N$2 -> 5.123851 | P13: =$N13*P$2/$N$2 -> 5.4695229 | Q13: =$N13*Q$2/$N$2 -> 5.8384841 | R13: =$N13*R$2/$N$2 -> 6.2323016 | S13: =$N13*S$2/$N$2 -> 6.6526477 | T13: =$N13*T$2/$N$2 -> 6.9183693 | U13: =$N13*U$2/$N$2 -> 7.1946664 | V13: =$N13*V$2/$N$2 -> 7.4819583 | ... AM13: =$N13*AM$2/$N$2 -> 9.0599953
A14: Austria | B14: KKO | C14: 1.2 | D14: 1.5 | E14: 1.8 | F14: 2 | G14: 2.3 | H14: 2.6 | I14: 3 | J14: 3.3 | K14: 3.6 | L14: 4 | M14: 4.3 | N14: 4.6 | O14: =$N14*O$2/$N$2 -> 4.9103572 | P14: =$N14*P$2/$N$2 -> 5.2416261 | Q14: =$N14*Q$2/$N$2 -> 5.5952139 | R14: =$N14*R$2/$N$2 -> 5.9726224 | S14: =$N14*S$2/$N$2 -> 6.375454 | T14: =$N14*T$2/$N$2 -> 6.6301039 | U14: =$N14*U$2/$N$2 -> 6.8948887 | V14: =$N14*V$2/$N$2 -> 7.1702101 | ... AM14: =$N14*AM$2/$N$2 -> 8.6824955
... A27: Luxembourg | B27: KKO | C27: 0.1 | D27: 0.11363636 | E27: 0.12727273 | F27: 0.14090909 | G27: 0.15454545 | H27: 0.16818182 | I27: 0.18181818 | J27: 0.19545455 | K27: 0.20909091 | L27: 0.22272727 | M27: 0.23636364 | N27: 0.25 | O27: =$N27*O$2/$N$2 -> 0.26686724 | P27: =$N27*P$2/$N$2 -> 0.28487098 | Q27: =$N27*Q$2/$N$2 -> 0.30408771 | R27: =$N27*R$2/$N$2 -> 0.32459904 | S27: =$N27*S$2/$N$2 -> 0.34649207 | T27: =$N27*T$2/$N$2 -> 0.36033174 | U27: =$N27*U$2/$N$2 -> 0.37472221 | V27: =$N27*V$2/$N$2 -> 0.38968533 | ... AM27: =$N27*AM$2/$N$2 -> 0.47187476
A28: Germany | B28: KVE | C28: ='input_EnBW Model 2026'!C3 -> 20.028514 | D28: ='input_EnBW Model 2026'!D3 -> 21.049013 | E28: ='input_EnBW Model 2026'!E3 -> 22.108105 | F28: ='input_EnBW Model 2026'!F3 -> 23.2057 | G28: ='input_EnBW Model 2026'!G3 -> 24.341472 | H28: ='input_EnBW Model 2026'!H3 -> 25.514813 | I28: ='input_EnBW Model 2026'!I3 -> 26.724801 | J28: ='input_EnBW Model 2026'!J3 -> 28.104956 | ... AM28: ='input_EnBW Model 2026'!AM3 -> 63.845991
A29: France | B29: KVE | C29: 11 | D29: 12.2 | E29: =E3*E$28/E$2 -> 12.689164 | F29: =F3*F$28/F$2 -> 13.545956 | G29: =G3*G$28/G$2 -> 14.437178 | H29: =H3*H$28/H$2 -> 15.270688 | I29: =I3*I$28/I$2 -> 16.133859 | J29: =J3*J$28/J$2 -> 17.203749 | K29: =K3*K$28/K$2 -> 18.329309 | L29: =L3*L$28/L$2 -> 19.42615 | ... N29: =N3*N$28/N$2 -> 21.455683 | O29: =$N29*O$28/$N$28 -> 22.635087 | P29: =$N29*P$28/$N$28 -> 23.879196 | Q29: =$N29*Q$28/$N$28 -> 25.191552 | R29: =$N29*R$28/$N$28 -> 26.575893 | S29: =$N29*S$28/$N$28 -> 28.036158 | T29: =$N29*T$28/$N$28 -> 29.155985 | U29: =$N29*U$28/$N$28 -> 30.32038 | V29: =$N29*V$28/$N$28 -> 31.53111 | ... AM29: =$N29*AM$28/$N$28 -> 39.859587
A30: Norway | B30: KVE | C30: 3.9 | D30: 4.9 | E30: =E4*E$28/E$2 -> 5.6817153 | F30: =F4*F$28/F$2 -> 6.5426047 | G30: =G4*G$28/G$2 -> 7.353097 | H30: =H4*H$28/H$2 -> 8.2025409 | I30: =I4*I$28/I$2 -> 9.0009951 | J30: =J4*J$28/J$2 -> 9.9865665 | K30: =K4*K$28/K$2 -> 10.864884 | L30: =L4*L$28/L$2 -> 11.721263 | ... N30: =N4*N$28/N$2 -> 13.369772 | O30: =$N30*O$28/$N$28 -> 14.1047 | P30: =$N30*P$28/$N$28 -> 14.879947 | Q30: =$N30*Q$28/$N$28 -> 15.697721 | R30: =$N30*R$28/$N$28 -> 16.560351 | S30: =$N30*S$28/$N$28 -> 17.470293 | T30: =$N30*T$28/$N$28 -> 18.168095 | U30: =$N30*U$28/$N$28 -> 18.89367 | V30: =$N30*V$28/$N$28 -> 19.648117 | ... AM30: =$N30*AM$28/$N$28 -> 24.837877
A31: Sweden | B31: KVE | C31: 2.9 | D31: 3.8 | E31: =E5*E$28/E$2 -> 4.5453723 | F31: =F5*F$28/F$2 -> 5.344663 | G31: =G5*G$28/G$2 -> 6.0976902 | H31: =H5*H$28/H$2 -> 6.8936248 | I31: =I5*I$28/I$2 -> 7.7272694 | J31: =J5*J$28/J$2 -> 8.5599142 | K31: =K5*K$28/K$2 -> 9.4549375 | L31: =L5*L$28/L$2 -> 10.327827 | ... N31: =N5*N$28/N$2 -> 11.928719 | O31: =$N31*O$28/$N$28 -> 12.584433 | P31: =$N31*P$28/$N$28 -> 13.27612 | Q31: =$N31*Q$28/$N$28 -> 14.005751 | R31: =$N31*R$28/$N$28 -> 14.775403 | S31: =$N31*S$28/$N$28 -> 15.587267 | T31: =$N31*T$28/$N$28 -> 16.209857 | U31: =$N31*U$28/$N$28 -> 16.857226 | V31: =$N31*V$28/$N$28 -> 17.530356 | ... AM31: =$N31*AM$28/$N$28 -> 22.160741
A32: Ireland | B32: KVE | C32: 6.8 | D32: 7.5 | E32: =E6*E$28/E$2 -> 7.6703157 | F32: =F6*F$28/F$2 -> 8.1091438 | G32: =G6*G$28/G$2 -> 8.4291599 | H32: =H6*H$28/H$2 -> 8.8133684 | I32: =I6*I$28/I$2 -> 9.0859102 | J32: =J6*J$28/J$2 -> 9.5669629 | K32: =K6*K$28/K$2 -> 9.9525658 | L32: =L6*L$28/L$2 -> 10.327827 | ... N32: =N6*N$28/N$2 -> 10.887958 | O32: =$N32*O$28/$N$28 -> 11.486462 | P32: =$N32*P$28/$N$28 -> 12.117801 | Q32: =$N32*Q$28/$N$28 -> 12.783773 | R32: =$N32*R$28/$N$28 -> 13.486274 | S32: =$N32*S$28/$N$28 -> 14.227304 | T32: =$N32*T$28/$N$28 -> 14.795575 | U32: =$N32*U$28/$N$28 -> 15.386462 | V32: =$N32*V$28/$N$28 -> 16.000862 | ... AM32: =$N32*AM$28/$N$28 -> 20.227253
A33: Netherlands | B33: KVE | C33: 8.4 | D33: 8.8 | E33: =E7*E$28/E$2 -> 8.8066588 | F33: =F7*F$28/F$2 -> 8.9384881 | G33: =G7*G$28/G$2 -> 9.1465353 | H33: =H7*H$28/H$2 -> 9.3369349 | I33: =I7*I$28/I$2 -> 9.5104854 | J33: =J7*J$28/J$2 -> 9.8187251 | K33: =K7*K$28/K$2 -> 10.118442 | L33: =L7*L$28/L$2 -> 10.409793 | ... N33: =N7*N$28/N$2 -> 10.887958 | O33: =$N33*O$28/$N$28 -> 11.486462 | P33: =$N33*P$28/$N$28 -> 12.117801 | Q33: =$N33*Q$28/$N$28 -> 12.783773 | R33: =$N33*R$28/$N$28 -> 13.486274 | S33: =$N33*S$28/$N$28 -> 14.227304 | T33: =$N33*T$28/$N$28 -> 14.795575 | U33: =$N33*U$28/$N$28 -> 15.386462 | V33: =$N33*V$28/$N$28 -> 16.000862 | ... AM33: =$N33*AM$28/$N$28 -> 20.227253
A34: Spain | B34: KVE | C34: 5.3 | D34: 5.8 | E34: =E8*E$28/E$2 -> 6.0604964 | F34: =F8*F$28/F$2 -> 6.4504553 | G34: =G8*G$28/G$2 -> 6.8150655 | H34: =H8*H$28/H$2 -> 7.2426691 | I34: =I8*I$28/I$2 -> 7.7272694 | J34: =J8*J$28/J$2 -> 8.2242312 | K34: =K8*K$28/K$2 -> 8.7914332 | L34: =L8*L$28/L$2 -> 9.2622571 | ... N34: =N8*N$28/N$2 -> 10.327549 | O34: =$N34*O$28/$N$28 -> 10.895247 | P34: =$N34*P$28/$N$28 -> 11.49409 | Q34: =$N34*Q$28/$N$28 -> 12.125784 | R34: =$N34*R$28/$N$28 -> 12.792127 | S34: =$N34*S$28/$N$28 -> 13.495016 | T34: =$N34*T$28/$N$28 -> 14.034038 | U34: =$N34*U$28/$N$28 -> 14.594511 | V34: =$N34*V$28/$N$28 -> 15.177288 | ... AM34: =$N34*AM$28/$N$28 -> 19.186145
A35: Italy | B35: KVE | C35: 3.6 | D35: 4.1 | E35: =E9*E$28/E$2 -> 4.3559818 | F35: =F9*F$28/F$2 -> 4.6996174 | G35: =G9*G$28/G$2 -> 5.1112991 | H35: =H9*H$28/H$2 -> 5.4974476 | I35: =I9*I$28/I$2 -> 5.9440534 | J35: =J9*J$28/J$2 -> 6.461896 | K35: =K9*K$28/K$2 -> 6.9667961 | L35: =L9*L$28/L$2 -> 7.5409527 | ... N35: =N9*N$28/N$2 -> 8.5662613 | O35: =$N35*O$28/$N$28 -> 9.0371428 | P35: =$N35*P$28/$N$28 -> 9.533858 | Q35: =$N35*Q$28/$N$28 -> 10.057821 | R35: =$N35*R$28/$N$28 -> 10.610524 | S35: =$N35*S$28/$N$28 -> 11.193541 | T35: =$N35*T$28/$N$28 -> 11.640636 | U35: =$N35*U$28/$N$28 -> 12.105525 | V35: =$N35*V$28/$N$28 -> 12.588913 | ... AM35: =$N35*AM$28/$N$28 -> 15.914089
A36: Denmark | B36: KVE | C36: 2 | D36: 2.6 | E36: =E10*E$28/E$2 -> 3.1249434 | F36: =F10*F$28/F$2 -> 3.6859745 | G36: =G10*G$28/G$2 -> 4.21458 | H36: =H10*H$28/H$2 -> 4.712098 | I36: =I10*I$28/I$2 -> 5.179818 | J36: =J10*J$28/J$2 -> 5.7066094 | K36: =K10*K$28/K$2 -> 6.2203537 | L36: =L10*L$28/L$2 -> 6.7212839 | ... N36: =N10*N$28/N$2 -> 7.6055591 | O36: =$N36*O$28/$N$28 -> 8.0236315 | P36: =$N36*P$28/$N$28 -> 8.4646402 | Q36: =$N36*Q$28/$N$28 -> 8.9298413 | R36: =$N36*R$28/$N$28 -> 9.420559 | S36: =$N36*S$28/$N$28 -> 9.9381904 | T36: =$N36*T$28/$N$28 -> 10.335144 | U36: =$N36*U$28/$N$28 -> 10.747896 | V36: =$N36*V$28/$N$28 -> 11.177073 | ... AM36: =$N36*AM$28/$N$28 -> 14.129331
A37: Finland | B37: KVE | C37: 1.5 | D37: 1.8 | E37: =E11*E$28/E$2 -> 2.0832956 | F37: =F11*F$28/F$2 -> 2.3958834 | G37: =G11*G$28/G$2 -> 2.6901574 | H37: =H11*H$28/H$2 -> 3.0541376 | I37: =I11*I$28/I$2 -> 3.3116869 | J37: =J11*J$28/J$2 -> 3.692512 | K37: =K11*K$28/K$2 -> 4.0639644 | L37: =L11*L$28/L$2 -> 4.3442445 | ... N37: =N11*N$28/N$2 -> 5.0436866 | O37: =$N37*O$28/$N$28 -> 5.3209346 | P37: =$N37*P$28/$N$28 -> 5.613393 | Q37: =$N37*Q$28/$N$28 -> 5.9218947 | R37: =$N37*R$28/$N$28 -> 6.2473181 | S37: =$N37*S$28/$N$28 -> 6.5905894 | T37: =$N37*T$28/$N$28 -> 6.8538323 | U37: =$N37*U$28/$N$28 -> 7.127552 | V37: =$N37*V$28/$N$28 -> 7.412164 | ... AM37: =$N37*AM$28/$N$28 -> 9.3699776
A38: Belgium | B38: KVE | C38: 2.2 | D38: 2.5 | E38: =E12*E$28/E$2 -> 2.5567719 | F38: =F12*F$28/F$2 -> 2.7644808 | G38: =G12*G$28/G$2 -> 2.8695013 | H38: =H12*H$28/H$2 -> 3.0541376 | I38: =I12*I$28/I$2 -> 3.2267718 | J38: =J12*J$28/J$2 -> 3.4407498 | K38: =K12*K$28/K$2 -> 3.6492741 | L38: =L12*L$28/L$2 -> 3.8524432 | ... N38: =N12*N$28/N$2 -> 4.3231599 | O38: =$N38*O$28/$N$28 -> 4.5608011 | P38: =$N38*P$28/$N$28 -> 4.8114797 | Q38: =$N38*Q$28/$N$28 -> 5.0759098 | R38: =$N38*R$28/$N$28 -> 5.3548441 | S38: =$N38*S$28/$N$28 -> 5.6490766 | T38: =$N38*T$28/$N$28 -> 5.8747134 | U38: =$N38*U$28/$N$28 -> 6.1093303 | V38: =$N38*V$28/$N$28 -> 6.3532834 | ... AM38: =$N38*AM$28/$N$28 -> 8.0314093
A39: Poland | B39: KVE | C39: 2.7 | D39: 2.9 | E39: =E13*E$28/E$2 -> 2.8408577 | F39: =F13*F$28/F$2 -> 2.9487796 | G39: =G13*G$28/G$2 -> 3.0488451 | H39: =H13*H$28/H$2 -> 3.0541376 | I39: =I13*I$28/I$2 -> 3.1418568 | J39: =J13*J$28/J$2 -> 3.2729084 | K39: =K13*K$28/K$2 -> 3.483398 | L39: =L13*L$28/L$2 -> 3.6065426 | ... N39: =N13*N$28/N$2 -> 3.8428088 | O39: =$N39*O$28/$N$28 -> 4.0540454 | P39: =$N39*P$28/$N$28 -> 4.2768709 | Q39: =$N39*Q$28/$N$28 -> 4.5119198 | R39: =$N39*R$28/$N$28 -> 4.7598614 | S39: =$N39*S$28/$N$28 -> 5.0214015 | T39: =$N39*T$28/$N$28 -> 5.2219675 | U39: =$N39*U$28/$N$28 -> 5.4305158 | V39: =$N39*V$28/$N$28 -> 5.647363 | ... AM39: =$N39*AM$28/$N$28 -> 7.1390305
A40: Austria | B40: KVE | C40: 1.2 | D40: 1.5 | E40: =E14*E$28/E$2 -> 1.7045146 | F40: =F14*F$28/F$2 -> 1.8429872 | G40: =G14*G$28/G$2 -> 2.062454 | H40: =H14*H$28/H$2 -> 2.2687879 | I40: =I14*I$28/I$2 -> 2.5474515 | J40: =J14*J$28/J$2 -> 2.769384 | K40: =K14*K$28/K$2 -> 2.9857698 | L40: =L14*L$28/L$2 -> 3.2786751 | ... N40: =N14*N$28/N$2 -> 3.6826918 | O40: =$N40*O$28/$N$28 -> 3.8851268 | P40: =$N40*P$28/$N$28 -> 4.0986679 | Q40: =$N40*Q$28/$N$28 -> 4.3239231 | R40: =$N40*R$28/$N$28 -> 4.5615338 | S40: =$N40*S$28/$N$28 -> 4.8121764 | T40: =$N40*T$28/$N$28 -> 5.0043855 | U40: =$N40*U$28/$N$28 -> 5.2042443 | V40: =$N40*V$28/$N$28 -> 5.4120562 | ... AM40: =$N40*AM$28/$N$28 -> 6.8415709
... A53: Luxembourg | B53: KVE | C53: 0.1 | D53: 0.10454545 | E53: =E27*E$28/E$2 -> 0.12052123 | F53: =F27*F$28/F$2 -> 0.12984683 | G53: =G27*G$28/G$2 -> 0.13858387 | H53: =H27*H$28/H$2 -> 0.14675726 | I53: =I27*I$28/I$2 -> 0.154391 | J53: =J27*J$28/J$2 -> 0.16402688 | K53: =K27*K$28/K$2 -> 0.17341592 | L53: =L27*L$28/L$2 -> 0.18256259 | ... N53: =N27*N$28/N$2 -> 0.20014629 | O53: =$N53*O$28/$N$28 -> 0.2111482 | P53: =$N53*P$28/$N$28 -> 0.22275369 | Q53: =$N53*Q$28/$N$28 -> 0.23499582 | R53: =$N53*R$28/$N$28 -> 0.24790945 | S53: =$N53*S$28/$N$28 -> 0.26153133 | T53: =$N53*T$28/$N$28 -> 0.27197747 | U53: =$N53*U$28/$N$28 -> 0.28283937 | V53: =$N53*V$28/$N$28 -> 0.29413349 | ... AM53: =$N53*AM$28/$N$28 -> 0.37182451
A54: Germany | B54: VWE | C54: ='input_EnBW Model 2026'!C4 -> 20.028514 | D54: ='input_EnBW Model 2026'!D4 -> 21.762956 | E54: ='input_EnBW Model 2026'!E4 -> 23.63935 | F54: ='input_EnBW Model 2026'!F4 -> 25.66823 | G54: ='input_EnBW Model 2026'!G4 -> 27.860759 | H54: ='input_EnBW Model 2026'!H4 -> 30.228747 | I54: ='input_EnBW Model 2026'!I4 -> 32.784662 | J54: ='input_EnBW Model 2026'!J4 -> 35.029273 | ... AM54: ='input_EnBW Model 2026'!AM4 -> 89.381752
A55: France | B55: VWE | C55: 11 | D55: 12.2 | E55: =E3*E$54/E$2 -> 13.568038 | F55: =F3*F$54/F$2 -> 14.983418 | G55: =G3*G$54/G$2 -> 16.524504 | H55: =H3*H$54/H$2 -> 18.091991 | I55: =I3*I$54/I$2 -> 19.792219 | J55: =J3*J$54/J$2 -> 21.442297 | K55: =K3*K$54/K$2 -> 23.209742 | L55: =L3*L$54/L$2 -> 24.990253 | ... N55: =N3*N$54/N$2 -> 28.483636 | O55: =$N55*O$54/$N$54 -> 30.546618 | P55: =$N55*P$54/$N$54 -> 32.758403 | Q55: =$N55*Q$54/$N$54 -> 35.129674 | R55: =$N55*R$54/$N$54 -> 37.671879 | S55: =$N55*S$54/$N$54 -> 40.397282 | T55: =$N55*T$54/$N$54 -> 42.110122 | U55: =$N55*U$54/$N$54 -> 43.894736 | V55: =$N55*V$54/$N$54 -> 45.754091 | ... AM55: =$N55*AM$54/$N$54 -> 55.801776
A56: Norway | B56: VWE | C56: 3.9 | D56: 4.9 | E56: =E4*E$54/E$2 -> 6.0752408 | F56: =F4*F$54/F$2 -> 7.236889 | G56: =G4*G$54/G$2 -> 8.4162068 | H56: =H4*H$54/H$2 -> 9.7179836 | I56: =I4*I$54/I$2 -> 11.041975 | J56: =J4*J$54/J$2 -> 12.446992 | K56: =K4*K$54/K$2 -> 13.757811 | L56: =L4*L$54/L$2 -> 15.078507 | ... N56: =N4*N$54/N$2 -> 17.749131 | O56: =$N56*O$54/$N$54 -> 19.034646 | P56: =$N56*P$54/$N$54 -> 20.412885 | Q56: =$N56*Q$54/$N$54 -> 21.890506 | R56: =$N56*R$54/$N$54 -> 23.474641 | S56: =$N56*S$54/$N$54 -> 25.172933 | T56: =$N56*T$54/$N$54 -> 26.240262 | U56: =$N56*U$54/$N$54 -> 27.352317 | V56: =$N56*V$54/$N$54 -> 28.510944 | ... AM56: =$N56*AM$54/$N$54 -> 34.772002
A57: Sweden | B57: VWE | C57: 2.9 | D57: 3.8 | E57: =E5*E$54/E$2 -> 4.8601926 | F57: =F5*F$54/F$2 -> 5.9118248 | G57: =G5*G$54/G$2 -> 6.9792934 | H57: =H5*H$54/H$2 -> 8.1672416 | I57: =I5*I$54/I$2 -> 9.4794311 | J57: =J5*J$54/J$2 -> 10.66885 | K57: =K5*K$54/K$2 -> 11.972446 | L57: =L5*L$54/L$2 -> 13.285957 | ... N57: =N5*N$54/N$2 -> 15.836051 | O57: =$N57*O$54/$N$54 -> 16.983008 | P57: =$N57*P$54/$N$54 -> 18.212694 | Q57: =$N57*Q$54/$N$54 -> 19.53105 | R57: =$N57*R$54/$N$54 -> 20.94444 | S57: =$N57*S$54/$N$54 -> 22.459683 | T57: =$N57*T$54/$N$54 -> 23.411971 | U57: =$N57*U$54/$N$54 -> 24.404163 | V57: =$N57*V$54/$N$54 -> 25.437909 | ... AM57: =$N57*AM$54/$N$54 -> 31.024122
A58: Ireland | B58: VWE | C58: 6.8 | D58: 7.5 | E58: =E6*E$54/E$2 -> 8.201575 | F58: =F6*F$54/F$2 -> 8.9696653 | G58: =G6*G$54/G$2 -> 9.6478468 | H58: =H6*H$54/H$2 -> 10.441663 | I58: =I6*I$54/I$2 -> 11.146144 | J58: =J6*J$54/J$2 -> 11.924009 | K58: =K6*K$54/K$2 -> 12.602575 | L58: =L6*L$54/L$2 -> 13.285957 | ... N58: =N6*N$54/N$2 -> 14.454382 | O58: =$N58*O$54/$N$54 -> 15.501269 | P58: =$N58*P$54/$N$54 -> 16.623667 | Q58: =$N58*Q$54/$N$54 -> 17.826999 | R58: =$N58*R$54/$N$54 -> 19.117073 | S58: =$N58*S$54/$N$54 -> 20.500113 | T58: =$N58*T$54/$N$54 -> 21.369315 | U58: =$N58*U$54/$N$54 -> 22.274941 | V58: =$N58*V$54/$N$54 -> 23.218494 | ... AM58: =$N58*AM$54/$N$54 -> 28.317319
A59: Netherlands | B59: VWE | C59: 8.4 | D59: 8.8 | E59: =E7*E$54/E$2 -> 9.4166232 | F59: =F7*F$54/F$2 -> 9.8870174 | G59: =G7*G$54/G$2 -> 10.46894 | H59: =H7*H$54/H$2 -> 11.06196 | I59: =I7*I$54/I$2 -> 11.666992 | J59: =J7*J$54/J$2 -> 12.237799 | K59: =K7*K$54/K$2 -> 12.812617 | L59: =L7*L$54/L$2 -> 13.391401 | ... N59: =N7*N$54/N$2 -> 14.454382 | O59: =$N59*O$54/$N$54 -> 15.501269 | P59: =$N59*P$54/$N$54 -> 16.623667 | Q59: =$N59*Q$54/$N$54 -> 17.826999 | R59: =$N59*R$54/$N$54 -> 19.117073 | S59: =$N59*S$54/$N$54 -> 20.500113 | T59: =$N59*T$54/$N$54 -> 21.369315 | U59: =$N59*U$54/$N$54 -> 22.274941 | V59: =$N59*V$54/$N$54 -> 23.218494 | ... AM59: =$N59*AM$54/$N$54 -> 28.317319
A60: Spain | B60: VWE | C60: 5.3 | D60: 5.8 | E60: =E8*E$54/E$2 -> 6.4802568 | F60: =F8*F$54/F$2 -> 7.134961 | G60: =G8*G$54/G$2 -> 7.8003868 | H60: =H8*H$54/H$2 -> 8.5807728 | I60: =I8*I$54/I$2 -> 9.4794311 | J60: =J8*J$54/J$2 -> 10.250464 | K60: =K8*K$54/K$2 -> 11.132274 | L60: =L8*L$54/L$2 -> 11.915184 | ... N60: =N8*N$54/N$2 -> 13.710407 | O60: =$N60*O$54/$N$54 -> 14.70341 | P60: =$N60*P$54/$N$54 -> 15.768037 | Q60: =$N60*Q$54/$N$54 -> 16.909433 | R60: =$N60*R$54/$N$54 -> 18.133106 | S60: =$N60*S$54/$N$54 -> 19.44496 | T60: =$N60*T$54/$N$54 -> 20.269424 | U60: =$N60*U$54/$N$54 -> 21.128436 | V60: =$N60*V$54/$N$54 -> 22.023424 | ... AM60: =$N60*AM$54/$N$54 -> 26.85981
A61: Italy | B61: VWE | C61: 3.6 | D61: 4.1 | E61: =E9*E$54/E$2 -> 4.6576846 | F61: =F9*F$54/F$2 -> 5.1983287 | G61: =G9*G$54/G$2 -> 5.8502901 | H61: =H9*H$54/H$2 -> 6.5131167 | I61: =I9*I$54/I$2 -> 7.2918701 | J61: =J9*J$54/J$2 -> 8.0539361 | K61: =K9*K$54/K$2 -> 8.8218022 | L61: =L9*L$54/L$2 -> 9.7008575 | ... N61: =N9*N$54/N$2 -> 11.372198 | O61: =$N61*O$54/$N$54 -> 12.195851 | P61: =$N61*P$54/$N$54 -> 13.078915 | Q61: =$N61*Q$54/$N$54 -> 14.025653 | R61: =$N61*R$54/$N$54 -> 15.040638 | S61: =$N61*S$54/$N$54 -> 16.128766 | T61: =$N61*T$54/$N$54 -> 16.812623 | U61: =$N61*U$54/$N$54 -> 17.525137 | V61: =$N61*V$54/$N$54 -> 18.267491 | ... AM61: =$N61*AM$54/$N$54 -> 22.279067
A62: Denmark | B62: VWE | C62: 2 | D62: 2.6 | E62: =E10*E$54/E$2 -> 3.3413824 | F62: =F10*F$54/F$2 -> 4.0771206 | G62: =G10*G$54/G$2 -> 4.8239234 | H62: =H10*H$54/H$2 -> 5.5826714 | I62: =I10*I$54/I$2 -> 6.3543439 | J62: =J10*J$54/J$2 -> 7.1125669 | K62: =K10*K$54/K$2 -> 7.8766091 | L62: =L10*L$54/L$2 -> 8.6464165 | ... N62: =N10*N$54/N$2 -> 10.096811 | O62: =$N62*O$54/$N$54 -> 10.828092 | P62: =$N62*P$54/$N$54 -> 11.61212 | Q62: =$N62*Q$54/$N$54 -> 12.452683 | R62: =$N62*R$54/$N$54 -> 13.353838 | S62: =$N62*S$54/$N$54 -> 14.319932 | T62: =$N62*T$54/$N$54 -> 14.927095 | U62: =$N62*U$54/$N$54 -> 15.559701 | V62: =$N62*V$54/$N$54 -> 16.218801 | ... AM62: =$N62*AM$54/$N$54 -> 19.78048
A63: Finland | B63: VWE | C63: 1.5 | D63: 1.8 | E63: =E11*E$54/E$2 -> 2.2275883 | F63: =F11*F$54/F$2 -> 2.6501284 | G63: =G11*G$54/G$2 -> 3.0791 | H63: =H11*H$54/H$2 -> 3.6183982 | I63: =I11*I$54/I$2 -> 4.0626133 | J63: =J11*J$54/J$2 -> 4.6022492 | K63: =K11*K$54/K$2 -> 5.1460513 | L63: =L11*L$54/L$2 -> 5.5885375 | ... N63: =N11*N$54/N$2 -> 6.69578 | O63: =$N63*O$54/$N$54 -> 7.1807349 | P63: =$N63*P$54/$N$54 -> 7.7006693 | Q63: =$N63*Q$54/$N$54 -> 8.258095 | R63: =$N63*R$54/$N$54 -> 8.8557028 | S63: =$N63*S$54/$N$54 -> 9.496376 | T63: =$N63*T$54/$N$54 -> 9.8990211 | U63: =$N63*U$54/$N$54 -> 10.318539 | V63: =$N63*V$54/$N$54 -> 10.755626 | ... AM63: =$N63*AM$54/$N$54 -> 13.117582
A64: Belgium | B64: VWE | C64: 2.2 | D64: 2.5 | E64: =E12*E$54/E$2 -> 2.7338583 | F64: =F12*F$54/F$2 -> 3.0578404 | G64: =G12*G$54/G$2 -> 3.2843734 | H64: =H12*H$54/H$2 -> 3.6183982 | I64: =I12*I$54/I$2 -> 3.9584438 | J64: =J12*J$54/J$2 -> 4.2884595 | K64: =K12*K$54/K$2 -> 4.620944 | L64: =L12*L$54/L$2 -> 4.9558729 | ... N64: =N12*N$54/N$2 -> 5.73924 | O64: =$N64*O$54/$N$54 -> 6.1549156 | P64: =$N64*P$54/$N$54 -> 6.6005737 | Q64: =$N64*Q$54/$N$54 -> 7.0783671 | R64: =$N64*R$54/$N$54 -> 7.5906024 | S64: =$N64*S$54/$N$54 -> 8.1397509 | T64: =$N64*T$54/$N$54 -> 8.4848753 | U64: =$N64*U$54/$N$54 -> 8.8444617 | V64: =$N64*V$54/$N$54 -> 9.2191078 | ... AM64: =$N64*AM$54/$N$54 -> 11.243642
...

Sheet input_EnBW Model 2026
C1: 2024 | D1: 2025 | E1: 2026 | F1: 2027 | G1: 2028 | H1: 2029 | I1: 2030 | J1: 2031 | K1: 2032 | L1: 2033 | M1: 2034 | N1: 2035 | O1: 2036 | P1: 2037 | Q1: 2038 | R1: 2039 | S1: 2040 | T1: 2041 | U1: 2042 | V1: 2043 | W1: 2044 | X1: 2045 | Y1: 2046 | Z1: 2047 | AA1: 2048 | AB1: 2049 | AC1: 2050 | AD1: 2051 | AE1: 2052 | AF1: 2053 | AG1: 2054 | AH1: 2055 | AI1: 2056 | AJ1: 2057 | AK1: 2058 | AL1: 2059 | AM1: 2060
A2: Germany | B2: KKO | C2: 20.028514 | D2: 21.630553 | E2: 23.346581 | F2: 25.182703 | G2: 27.145034 | H2: 29.239628 | I2: 31.472397 | J2: 33.489886 | K2: 35.63578 | L2: 37.918184 | M2: 40.345709 | N2: 42.927504 | O2: 45.823777 | P2: 48.915201 | Q2: 52.214906 | R2: 55.736906 | S2: 59.496158 | T2: 61.872568 | U2: 64.343556 | V2: 66.912874 | W2: 69.584419 | X2: 72.362244 | Y2: 74.46446 | Z2: 76.115432 | AA2: 77.406003 | AB2: 78.408729 | AC2: 79.181558 | AD2: 79.770773 | AE2: 80.213341 | AF2: 80.538785 | AG2: 80.770687 | AH2: 80.927878 | AI2: 81.025401 | AJ2: 81.075269 | AK2: 81.087077 | AL2: 81.068488 | AM2: 81.025621
B3: KVE | C3: 20.028514 | D3: 21.049013 | E3: 22.108105 | F3: 23.2057 | G3: 24.341472 | H3: 25.514813 | I3: 26.724801 | J3: 28.104956 | K3: 29.555621 | L3: 31.080351 | M3: 32.68288 | N3: 34.367123 | O3: 36.25626 | P3: 38.24904 | Q3: 40.351136 | R3: 42.568535 | S3: 44.907548 | T3: 46.701256 | U3: 48.566352 | V3: 50.505666 | W3: 52.522141 | X3: 54.618837 | Y3: 56.310445 | Z3: 57.729152 | AA3: 58.916272 | AB3: 59.906865 | AC3: 60.730685 | AD3: 61.412981 | AE3: 61.97518 | AF3: 62.435464 | AG3: 62.809263 | AH3: 63.109673 | AI3: 63.347804 | AJ3: 63.533087 | AK3: 63.673524 | AL3: 63.775905 | AM3: 63.845991
B4: VWE | C4: 20.028514 | D4: 21.762956 | E4: 23.63935 | F4: 25.66823 | G4: 27.860759 | H4: 30.228747 | I4: 32.784662 | J4: 35.029273 | K4: 37.425215 | L4: 39.982489 | M4: 42.711743 | N4: 45.624305 | O4: 48.928734 | P4: 52.47151 | Q4: 56.269746 | R4: 60.34178 | S4: 64.707257 | T4: 67.450836 | U4: 70.309382 | V4: 73.287645 | W4: 76.390567 | X4: 79.623292 | Y4: 82.125537 | Z4: 84.1243 | AA4: 85.706847 | AB4: 86.945324 | AC4: 87.899374 | AD4: 88.618307 | AE4: 89.142887 | AF4: 89.506814 | AG4: 89.737944 | AH4: 89.859308 | AI4: 89.889943 | AJ4: 89.845585 | AK4: 89.739243 | AL4: 89.581669 | AM4: 89.381752
B5: VNI | C5: 20.028514 | D5: 20.799963 | E5: 21.597575 | F5: 22.421993 | G5: 23.273855 | H5: 24.153793 | I5: 25.062434 | J5: 25.836571 | K5: 26.631625 | L5: 27.447994 | M5: 28.286072 | N5: 29.146252 | O5: 30.218676 | P5: 31.329782 | Q5: 32.480932 | R5: 33.67353 | S5: 34.909031 | T5: 36.01495 | U5: 37.154947 | V5: 38.33003 | W5: 39.541239 | X5: 40.789641 | Y5: 41.755726 | Z5: 42.53614 | AA5: 43.159469 | AB5: 43.649901 | AC5: 44.027901 | AD5: 44.310785 | AE5: 44.513206 | AF5: 44.647558 | AG5: 44.724329 | AH5: 44.752391 | AI5: 44.739253 | AJ5: 44.691263 | AK5: 44.613795 | AL5: 44.511393 | AM5: 44.387901
B26: ICIS | C26: 20.6 | D26: 22.4 | E26: 24.3 | F26: 26.3 | G26: 28.3 | H26: 30.5 | I26: 32.7 | J26: 34.9 | K26: 37.2 | L26: 39.5 | M26: 41.7 | N26: 43.9
B27: Ratio KKO/ICIS | C27: =C2/C26 -> 0.97225794 | D27: =D2/D26 -> 0.96564969 | E27: =E2/E26 -> 0.96076465 | F27: =F2/F26 -> 0.95751724 | G27: =G2/G26 -> 0.95918849 | H27: =H2/H26 -> 0.95867632 | I27: =I2/I26 -> 0.96245863 | J27: =J2/J26 -> 0.95959559 | ... N27: =N2/N26 -> 0.97784746
B28: Average KKO/ICIS | C28: =AVERAGE(C27:N27) -> 0.96328201
B30: Ratio KVE/ICIS | C30: =C3/C26 -> 0.97225794 | D30: =D3/D26 -> 0.93968808 | E30: =E3/E26 -> 0.90979854 | F30: =F3/F26 -> 0.88234602 | G30: =G3/G26 -> 0.86012268 | H30: =H3/H26 -> 0.83655125 | I30: =I3/I26 -> 0.81727221 | J30: =J3/J26 -> 0.8052996 | ... N30: =N3/N26 -> 0.78285018
B31: Average KVE/ICIS | C31: =AVERAGE(C30:N30) -> 0.84760824
B33: Ratio VWE/ICIS | C33: =C4/C26 -> 0.97225794 | D33: =D4/D26 -> 0.97156054 | E33: =E4/E26 -> 0.97281276 | F33: =F4/F26 -> 0.97597831 | G33: =G4/G26 -> 0.9844791 | H33: =H4/H26 -> 0.99110647 | I33: =I4/I26 -> 1.002589 | J33: =J4/J26 -> 1.0037041 | ... N33: =N4/N26 -> 1.039278
B34: Average VWE/ICIS | C34: =AVERAGE(C33:N33) -> 0.99635815
B36: Ratio VNI/ICIS | C36: =C5/C26 -> 0.97225794 | D36: =D5/D26 -> 0.92856978 | E36: =E5/E26 -> 0.88878911 | F36: =F5/F26 -> 0.85254727 | G36: =G5/G26 -> 0.82239769 | H36: =H5/H26 -> 0.79192765 | I36: =I5/I26 -> 0.7664353 | J36: =J5/J26 -> 0.7403029 | ... N36: =N5/N26 -> 0.66392374
B37: Average VNI/ICIS | C37: =AVERAGE(C36:N36) -> 0.79302202
